2025-09-18 19:43:41,721 - ERROR - Fail at 158: https://www.flashscore.com/match/football/augsburg-fTVNku3I/union-berlin-pzHW4oaE/?mid=6XPfpBjd
Traceback (most recent call last):
  File "c:\Users\GPbl3YH\Desktop\Study\PythonProjects\trash\football_stats_scraper\main.py", line 27, in <module>
    write_stats_to_database(m, conn)
  File "c:\Users\GPbl3YH\Desktop\Study\PythonProjects\trash\football_stats_scraper\common\utils.py", line 28, in write_stats_to_database
    (match.DATE, match.HOME, match.AWAY, match.STATS['full_time']['Ball Possession'][0], match.STATS['full_time']['Ball Possession'][1], match.STATS['full_time']['Total shots'][0], match.STATS['full_time']['Total shots'][1], match.STATS['full_time']['Shots on target'][0], match.STATS['full_time']['Shots on target'][1], match.STATS['full_time']['Big Chances'][0], match.STATS['full_time']['Big Chances'][1]))
                                         ~~~~~~~~~~~~~~~~~~~~~~~~^^^^^^^^^^^^^^^^^^^
KeyError: 'Ball Possession'
2025-09-18 20:03:18,302 - ERROR - Fail at 190: https://www.flashscore.com/match/football/bochum-8Y2m6ADe/union-berlin-pzHW4oaE/?mid=zgDdPU2e
Traceback (most recent call last):
  File "c:\Users\GPbl3YH\Desktop\Study\PythonProjects\trash\football_stats_scraper\main.py", line 25, in <module>
    m = Match(x, options)
        ^^^^^^^^^^^^^^^^^
  File "c:\Users\GPbl3YH\Desktop\Study\PythonProjects\trash\football_stats_scraper\common\models.py", line 23, in __init__
    self.write_stats()
  File "c:\Users\GPbl3YH\Desktop\Study\PythonProjects\trash\football_stats_scraper\common\models.py", line 49, in write_stats
    self.STATS['second_half']['Goals'] = goals[1]
                                         ~~~~~^^^
IndexError: list index out of range
2025-09-18 20:21:51,269 - ERROR - Fail at 219: https://www.flashscore.com/match/football/heidenheim-KWixEVWi/wolfsburg-nwkTahLL/?mid=xMovyDqH
Traceback (most recent call last):
  File "c:\Users\GPbl3YH\Desktop\Study\PythonProjects\trash\football_stats_scraper\main.py", line 27, in <module>
    write_stats_to_database(m, conn)
  File "c:\Users\GPbl3YH\Desktop\Study\PythonProjects\trash\football_stats_scraper\common\utils.py", line 28, in write_stats_to_database
    (match.DATE, match.HOME, match.AWAY, match.STATS['full_time']['Ball Possession'][0], match.STATS['full_time']['Ball Possession'][1], match.STATS['full_time']['Total shots'][0], match.STATS['full_time']['Total shots'][1], match.STATS['full_time']['Shots on target'][0], match.STATS['full_time']['Shots on target'][1], match.STATS['full_time']['Big Chances'][0], match.STATS['full_time']['Big Chances'][1]))
                                                                                                                                                                                                                                                                                                                                 ~~~~~~~~~~~~~~~~~~~~~~~~^^^^^^^^^^^^^^^
KeyError: 'Big Chances'
2025-09-18 20:22:26,755 - ERROR - Fail at 220: https://www.flashscore.com/match/football/eintracht-frankfurt-8vndvXTk/vfb-stuttgart-nJQmYp1B/?mid=UkaNveph
Traceback (most recent call last):
  File "c:\Users\GPbl3YH\Desktop\Study\PythonProjects\trash\football_stats_scraper\main.py", line 27, in <module>
    write_stats_to_database(m, conn)
  File "c:\Users\GPbl3YH\Desktop\Study\PythonProjects\trash\football_stats_scraper\common\utils.py", line 28, in write_stats_to_database
    (match.DATE, match.HOME, match.AWAY, match.STATS['full_time']['Ball Possession'][0], match.STATS['full_time']['Ball Possession'][1], match.STATS['full_time']['Total shots'][0], match.STATS['full_time']['Total shots'][1], match.STATS['full_time']['Shots on target'][0], match.STATS['full_time']['Shots on target'][1], match.STATS['full_time']['Big Chances'][0], match.STATS['full_time']['Big Chances'][1]))
                                                                                                                                                                                                                                                                                                                                 ~~~~~~~~~~~~~~~~~~~~~~~~^^^^^^^^^^^^^^^
KeyError: 'Big Chances'
2025-09-18 20:23:06,289 - ERROR - Fail at 221: https://www.flashscore.com/match/football/augsburg-fTVNku3I/hoffenheim-hQAtP9Sl/?mid=UJQITUyi
Traceback (most recent call last):
  File "c:\Users\GPbl3YH\Desktop\Study\PythonProjects\trash\football_stats_scraper\main.py", line 27, in <module>
    write_stats_to_database(m, conn)
  File "c:\Users\GPbl3YH\Desktop\Study\PythonProjects\trash\football_stats_scraper\common\utils.py", line 28, in write_stats_to_database
    (match.DATE, match.HOME, match.AWAY, match.STATS['full_time']['Ball Possession'][0], match.STATS['full_time']['Ball Possession'][1], match.STATS['full_time']['Total shots'][0], match.STATS['full_time']['Total shots'][1], match.STATS['full_time']['Shots on target'][0], match.STATS['full_time']['Shots on target'][1], match.STATS['full_time']['Big Chances'][0], match.STATS['full_time']['Big Chances'][1]))
                                                                                                                                                                                                                                                                                                                                 ~~~~~~~~~~~~~~~~~~~~~~~~^^^^^^^^^^^^^^^
KeyError: 'Big Chances'
2025-09-18 20:23:44,219 - ERROR - Fail at 222: https://www.flashscore.com/match/football/b-monchengladbach-88HSzjDr/rb-leipzig-KbS1suSm/?mid=j5mWxZE4
Traceback (most recent call last):
  File "c:\Users\GPbl3YH\Desktop\Study\PythonProjects\trash\football_stats_scraper\main.py", line 27, in <module>
    write_stats_to_database(m, conn)
  File "c:\Users\GPbl3YH\Desktop\Study\PythonProjects\trash\football_stats_scraper\common\utils.py", line 28, in write_stats_to_database
    (match.DATE, match.HOME, match.AWAY, match.STATS['full_time']['Ball Possession'][0], match.STATS['full_time']['Ball Possession'][1], match.STATS['full_time']['Total shots'][0], match.STATS['full_time']['Total shots'][1], match.STATS['full_time']['Shots on target'][0], match.STATS['full_time']['Shots on target'][1], match.STATS['full_time']['Big Chances'][0], match.STATS['full_time']['Big Chances'][1]))
                                                                                                                                                                                                                                                                                                                                 ~~~~~~~~~~~~~~~~~~~~~~~~^^^^^^^^^^^^^^^
KeyError: 'Big Chances'
2025-09-18 20:24:21,578 - ERROR - Fail at 223: https://www.flashscore.com/match/football/bayer-leverkusen-4jcj2zMd/bochum-8Y2m6ADe/?mid=biQrHC9r
Traceback (most recent call last):
  File "c:\Users\GPbl3YH\Desktop\Study\PythonProjects\trash\football_stats_scraper\main.py", line 27, in <module>
    write_stats_to_database(m, conn)
  File "c:\Users\GPbl3YH\Desktop\Study\PythonProjects\trash\football_stats_scraper\common\utils.py", line 28, in write_stats_to_database
    (match.DATE, match.HOME, match.AWAY, match.STATS['full_time']['Ball Possession'][0], match.STATS['full_time']['Ball Possession'][1], match.STATS['full_time']['Total shots'][0], match.STATS['full_time']['Total shots'][1], match.STATS['full_time']['Shots on target'][0], match.STATS['full_time']['Shots on target'][1], match.STATS['full_time']['Big Chances'][0], match.STATS['full_time']['Big Chances'][1]))
                                                                                                                                                                                                                                                                                                                                 ~~~~~~~~~~~~~~~~~~~~~~~~^^^^^^^^^^^^^^^
KeyError: 'Big Chances'
2025-09-18 20:25:04,367 - ERROR - Fail at 224: https://www.flashscore.com/match/football/dortmund-nP1i5US1/mainz-EuakNmc1/?mid=nee3ysec
Traceback (most recent call last):
  File "c:\Users\GPbl3YH\Desktop\Study\PythonProjects\trash\football_stats_scraper\main.py", line 27, in <module>
    write_stats_to_database(m, conn)
  File "c:\Users\GPbl3YH\Desktop\Study\PythonProjects\trash\football_stats_scraper\common\utils.py", line 28, in write_stats_to_database
    (match.DATE, match.HOME, match.AWAY, match.STATS['full_time']['Ball Possession'][0], match.STATS['full_time']['Ball Possession'][1], match.STATS['full_time']['Total shots'][0], match.STATS['full_time']['Total shots'][1], match.STATS['full_time']['Shots on target'][0], match.STATS['full_time']['Shots on target'][1], match.STATS['full_time']['Big Chances'][0], match.STATS['full_time']['Big Chances'][1]))
                                                                                                                                                                                                                                                                                                                                 ~~~~~~~~~~~~~~~~~~~~~~~~^^^^^^^^^^^^^^^
KeyError: 'Big Chances'
2025-09-18 20:25:39,349 - ERROR - Fail at 225: https://www.flashscore.com/match/football/bayern-munich-nVp0wiqd/st-pauli-ILyJuN3g/?mid=6HTjFjve
Traceback (most recent call last):
  File "c:\Users\GPbl3YH\Desktop\Study\PythonProjects\trash\football_stats_scraper\main.py", line 27, in <module>
    write_stats_to_database(m, conn)
  File "c:\Users\GPbl3YH\Desktop\Study\PythonProjects\trash\football_stats_scraper\common\utils.py", line 28, in write_stats_to_database
    (match.DATE, match.HOME, match.AWAY, match.STATS['full_time']['Ball Possession'][0], match.STATS['full_time']['Ball Possession'][1], match.STATS['full_time']['Total shots'][0], match.STATS['full_time']['Total shots'][1], match.STATS['full_time']['Shots on target'][0], match.STATS['full_time']['Shots on target'][1], match.STATS['full_time']['Big Chances'][0], match.STATS['full_time']['Big Chances'][1]))
                                                                                                                                                                                                                                                                                                                                 ~~~~~~~~~~~~~~~~~~~~~~~~^^^^^^^^^^^^^^^
KeyError: 'Big Chances'
2025-09-18 20:26:29,362 - ERROR - Fail at 226: https://www.flashscore.com/match/football/holstein-kiel-63WsD2ei/werder-bremen-Ig1f1fy3/?mid=YmumZjET
Traceback (most recent call last):
  File "c:\Users\GPbl3YH\Desktop\Study\PythonProjects\trash\football_stats_scraper\main.py", line 27, in <module>
    write_stats_to_database(m, conn)
  File "c:\Users\GPbl3YH\Desktop\Study\PythonProjects\trash\football_stats_scraper\common\utils.py", line 28, in write_stats_to_database
    (match.DATE, match.HOME, match.AWAY, match.STATS['full_time']['Ball Possession'][0], match.STATS['full_time']['Ball Possession'][1], match.STATS['full_time']['Total shots'][0], match.STATS['full_time']['Total shots'][1], match.STATS['full_time']['Shots on target'][0], match.STATS['full_time']['Shots on target'][1], match.STATS['full_time']['Big Chances'][0], match.STATS['full_time']['Big Chances'][1]))
                                                                                                                                                                                                                                                                                                                                 ~~~~~~~~~~~~~~~~~~~~~~~~^^^^^^^^^^^^^^^
KeyError: 'Big Chances'
2025-09-18 20:27:06,275 - ERROR - Fail at 227: https://www.flashscore.com/match/football/freiburg-fiEQZ7C7/union-berlin-pzHW4oaE/?mid=v3DAZKP9
Traceback (most recent call last):
  File "c:\Users\GPbl3YH\Desktop\Study\PythonProjects\trash\football_stats_scraper\main.py", line 27, in <module>
    write_stats_to_database(m, conn)
  File "c:\Users\GPbl3YH\Desktop\Study\PythonProjects\trash\football_stats_scraper\common\utils.py", line 28, in write_stats_to_database
    (match.DATE, match.HOME, match.AWAY, match.STATS['full_time']['Ball Possession'][0], match.STATS['full_time']['Ball Possession'][1], match.STATS['full_time']['Total shots'][0], match.STATS['full_time']['Total shots'][1], match.STATS['full_time']['Shots on target'][0], match.STATS['full_time']['Shots on target'][1], match.STATS['full_time']['Big Chances'][0], match.STATS['full_time']['Big Chances'][1]))
                                                                                                                                                                                                                                                                                                                                 ~~~~~~~~~~~~~~~~~~~~~~~~^^^^^^^^^^^^^^^
KeyError: 'Big Chances'
2025-09-18 20:27:42,147 - ERROR - Fail at 228: https://www.flashscore.com/match/football/b-monchengladbach-88HSzjDr/werder-bremen-Ig1f1fy3/?mid=raQ4MDUN
Traceback (most recent call last):
  File "c:\Users\GPbl3YH\Desktop\Study\PythonProjects\trash\football_stats_scraper\main.py", line 27, in <module>
    write_stats_to_database(m, conn)
  File "c:\Users\GPbl3YH\Desktop\Study\PythonProjects\trash\football_stats_scraper\common\utils.py", line 28, in write_stats_to_database
    (match.DATE, match.HOME, match.AWAY, match.STATS['full_time']['Ball Possession'][0], match.STATS['full_time']['Ball Possession'][1], match.STATS['full_time']['Total shots'][0], match.STATS['full_time']['Total shots'][1], match.STATS['full_time']['Shots on target'][0], match.STATS['full_time']['Shots on target'][1], match.STATS['full_time']['Big Chances'][0], match.STATS['full_time']['Big Chances'][1]))
                                                                                                                                                                                                                                                                                                                                 ~~~~~~~~~~~~~~~~~~~~~~~~^^^^^^^^^^^^^^^
KeyError: 'Big Chances'
2025-09-18 20:28:17,741 - ERROR - Fail at 229: https://www.flashscore.com/match/football/freiburg-fiEQZ7C7/mainz-EuakNmc1/?mid=GnZmQeVb
Traceback (most recent call last):
  File "c:\Users\GPbl3YH\Desktop\Study\PythonProjects\trash\football_stats_scraper\main.py", line 27, in <module>
    write_stats_to_database(m, conn)
  File "c:\Users\GPbl3YH\Desktop\Study\PythonProjects\trash\football_stats_scraper\common\utils.py", line 28, in write_stats_to_database
    (match.DATE, match.HOME, match.AWAY, match.STATS['full_time']['Ball Possession'][0], match.STATS['full_time']['Ball Possession'][1], match.STATS['full_time']['Total shots'][0], match.STATS['full_time']['Total shots'][1], match.STATS['full_time']['Shots on target'][0], match.STATS['full_time']['Shots on target'][1], match.STATS['full_time']['Big Chances'][0], match.STATS['full_time']['Big Chances'][1]))
                                                                                                                                                                                                                                                                                                                                 ~~~~~~~~~~~~~~~~~~~~~~~~^^^^^^^^^^^^^^^
KeyError: 'Big Chances'
2025-09-18 20:28:52,504 - ERROR - Fail at 230: https://www.flashscore.com/match/football/dortmund-nP1i5US1/rb-leipzig-KbS1suSm/?mid=dr2N9zoI
Traceback (most recent call last):
  File "c:\Users\GPbl3YH\Desktop\Study\PythonProjects\trash\football_stats_scraper\main.py", line 27, in <module>
    write_stats_to_database(m, conn)
  File "c:\Users\GPbl3YH\Desktop\Study\PythonProjects\trash\football_stats_scraper\common\utils.py", line 28, in write_stats_to_database
    (match.DATE, match.HOME, match.AWAY, match.STATS['full_time']['Ball Possession'][0], match.STATS['full_time']['Ball Possession'][1], match.STATS['full_time']['Total shots'][0], match.STATS['full_time']['Total shots'][1], match.STATS['full_time']['Shots on target'][0], match.STATS['full_time']['Shots on target'][1], match.STATS['full_time']['Big Chances'][0], match.STATS['full_time']['Big Chances'][1]))
                                                                                                                                                                                                                                                                                                                                 ~~~~~~~~~~~~~~~~~~~~~~~~^^^^^^^^^^^^^^^
KeyError: 'Big Chances'
2025-09-18 20:29:28,403 - ERROR - Fail at 231: https://www.flashscore.com/match/football/bayern-munich-nVp0wiqd/union-berlin-pzHW4oaE/?mid=jVWMBdG5
Traceback (most recent call last):
  File "c:\Users\GPbl3YH\Desktop\Study\PythonProjects\trash\football_stats_scraper\main.py", line 27, in <module>
    write_stats_to_database(m, conn)
  File "c:\Users\GPbl3YH\Desktop\Study\PythonProjects\trash\football_stats_scraper\common\utils.py", line 28, in write_stats_to_database
    (match.DATE, match.HOME, match.AWAY, match.STATS['full_time']['Ball Possession'][0], match.STATS['full_time']['Ball Possession'][1], match.STATS['full_time']['Total shots'][0], match.STATS['full_time']['Total shots'][1], match.STATS['full_time']['Shots on target'][0], match.STATS['full_time']['Shots on target'][1], match.STATS['full_time']['Big Chances'][0], match.STATS['full_time']['Big Chances'][1]))
                                                                                                                                                                                                                                                                                                                                 ~~~~~~~~~~~~~~~~~~~~~~~~^^^^^^^^^^^^^^^
KeyError: 'Big Chances'
2025-09-18 20:30:03,227 - ERROR - Fail at 232: https://www.flashscore.com/match/football/bochum-8Y2m6ADe/eintracht-frankfurt-8vndvXTk/?mid=485V7EFU
Traceback (most recent call last):
  File "c:\Users\GPbl3YH\Desktop\Study\PythonProjects\trash\football_stats_scraper\main.py", line 27, in <module>
    write_stats_to_database(m, conn)
  File "c:\Users\GPbl3YH\Desktop\Study\PythonProjects\trash\football_stats_scraper\common\utils.py", line 28, in write_stats_to_database
    (match.DATE, match.HOME, match.AWAY, match.STATS['full_time']['Ball Possession'][0], match.STATS['full_time']['Ball Possession'][1], match.STATS['full_time']['Total shots'][0], match.STATS['full_time']['Total shots'][1], match.STATS['full_time']['Shots on target'][0], match.STATS['full_time']['Shots on target'][1], match.STATS['full_time']['Big Chances'][0], match.STATS['full_time']['Big Chances'][1]))
                                                                                                                                                                                                                                                                                                                                 ~~~~~~~~~~~~~~~~~~~~~~~~^^^^^^^^^^^^^^^
KeyError: 'Big Chances'
2025-09-18 20:30:39,142 - ERROR - Fail at 233: https://www.flashscore.com/match/football/hoffenheim-hQAtP9Sl/st-pauli-ILyJuN3g/?mid=8MVuSH0n
Traceback (most recent call last):
  File "c:\Users\GPbl3YH\Desktop\Study\PythonProjects\trash\football_stats_scraper\main.py", line 27, in <module>
    write_stats_to_database(m, conn)
  File "c:\Users\GPbl3YH\Desktop\Study\PythonProjects\trash\football_stats_scraper\common\utils.py", line 28, in write_stats_to_database
    (match.DATE, match.HOME, match.AWAY, match.STATS['full_time']['Ball Possession'][0], match.STATS['full_time']['Ball Possession'][1], match.STATS['full_time']['Total shots'][0], match.STATS['full_time']['Total shots'][1], match.STATS['full_time']['Shots on target'][0], match.STATS['full_time']['Shots on target'][1], match.STATS['full_time']['Big Chances'][0], match.STATS['full_time']['Big Chances'][1]))
                                                                                                                                                                                                                                                                                                                                 ~~~~~~~~~~~~~~~~~~~~~~~~^^^^^^^^^^^^^^^
KeyError: 'Big Chances'
2025-09-18 20:31:13,442 - ERROR - Fail at 234: https://www.flashscore.com/match/football/heidenheim-KWixEVWi/holstein-kiel-63WsD2ei/?mid=2q7yHiho
Traceback (most recent call last):
  File "c:\Users\GPbl3YH\Desktop\Study\PythonProjects\trash\football_stats_scraper\main.py", line 27, in <module>
    write_stats_to_database(m, conn)
  File "c:\Users\GPbl3YH\Desktop\Study\PythonProjects\trash\football_stats_scraper\common\utils.py", line 28, in write_stats_to_database
    (match.DATE, match.HOME, match.AWAY, match.STATS['full_time']['Ball Possession'][0], match.STATS['full_time']['Ball Possession'][1], match.STATS['full_time']['Total shots'][0], match.STATS['full_time']['Total shots'][1], match.STATS['full_time']['Shots on target'][0], match.STATS['full_time']['Shots on target'][1], match.STATS['full_time']['Big Chances'][0], match.STATS['full_time']['Big Chances'][1]))
                                                                                                                                                                                                                                                                                                                                 ~~~~~~~~~~~~~~~~~~~~~~~~^^^^^^^^^^^^^^^
KeyError: 'Big Chances'
2025-09-18 20:31:53,255 - ERROR - Fail at 235: https://www.flashscore.com/match/football/augsburg-fTVNku3I/wolfsburg-nwkTahLL/?mid=AoSdOZaB
Traceback (most recent call last):
  File "c:\Users\GPbl3YH\Desktop\Study\PythonProjects\trash\football_stats_scraper\main.py", line 27, in <module>
    write_stats_to_database(m, conn)
  File "c:\Users\GPbl3YH\Desktop\Study\PythonProjects\trash\football_stats_scraper\common\utils.py", line 28, in write_stats_to_database
    (match.DATE, match.HOME, match.AWAY, match.STATS['full_time']['Ball Possession'][0], match.STATS['full_time']['Ball Possession'][1], match.STATS['full_time']['Total shots'][0], match.STATS['full_time']['Total shots'][1], match.STATS['full_time']['Shots on target'][0], match.STATS['full_time']['Shots on target'][1], match.STATS['full_time']['Big Chances'][0], match.STATS['full_time']['Big Chances'][1]))
                                                                                                                                                                                                                                                                                                                                 ~~~~~~~~~~~~~~~~~~~~~~~~^^^^^^^^^^^^^^^
KeyError: 'Big Chances'
2025-09-18 20:32:28,489 - ERROR - Fail at 236: https://www.flashscore.com/match/football/bayer-leverkusen-4jcj2zMd/vfb-stuttgart-nJQmYp1B/?mid=IHYEDIog
Traceback (most recent call last):
  File "c:\Users\GPbl3YH\Desktop\Study\PythonProjects\trash\football_stats_scraper\main.py", line 27, in <module>
    write_stats_to_database(m, conn)
  File "c:\Users\GPbl3YH\Desktop\Study\PythonProjects\trash\football_stats_scraper\common\utils.py", line 28, in write_stats_to_database
    (match.DATE, match.HOME, match.AWAY, match.STATS['full_time']['Ball Possession'][0], match.STATS['full_time']['Ball Possession'][1], match.STATS['full_time']['Total shots'][0], match.STATS['full_time']['Total shots'][1], match.STATS['full_time']['Shots on target'][0], match.STATS['full_time']['Shots on target'][1], match.STATS['full_time']['Big Chances'][0], match.STATS['full_time']['Big Chances'][1]))
                                                                                                                                                                                                                                                                                                                                 ~~~~~~~~~~~~~~~~~~~~~~~~^^^^^^^^^^^^^^^
KeyError: 'Big Chances'
2025-09-18 20:33:04,667 - ERROR - Fail at 237: https://www.flashscore.com/match/football/heidenheim-KWixEVWi/hoffenheim-hQAtP9Sl/?mid=zyC4c6ee
Traceback (most recent call last):
  File "c:\Users\GPbl3YH\Desktop\Study\PythonProjects\trash\football_stats_scraper\main.py", line 27, in <module>
    write_stats_to_database(m, conn)
  File "c:\Users\GPbl3YH\Desktop\Study\PythonProjects\trash\football_stats_scraper\common\utils.py", line 28, in write_stats_to_database
    (match.DATE, match.HOME, match.AWAY, match.STATS['full_time']['Ball Possession'][0], match.STATS['full_time']['Ball Possession'][1], match.STATS['full_time']['Total shots'][0], match.STATS['full_time']['Total shots'][1], match.STATS['full_time']['Shots on target'][0], match.STATS['full_time']['Shots on target'][1], match.STATS['full_time']['Big Chances'][0], match.STATS['full_time']['Big Chances'][1]))
                                                                                                                                                                                                                                                                                                                                 ~~~~~~~~~~~~~~~~~~~~~~~~^^^^^^^^^^^^^^^
KeyError: 'Big Chances'
2025-09-18 20:33:39,646 - ERROR - Fail at 238: https://www.flashscore.com/match/football/eintracht-frankfurt-8vndvXTk/union-berlin-pzHW4oaE/?mid=ABBmcc1C
Traceback (most recent call last):
  File "c:\Users\GPbl3YH\Desktop\Study\PythonProjects\trash\football_stats_scraper\main.py", line 27, in <module>
    write_stats_to_database(m, conn)
  File "c:\Users\GPbl3YH\Desktop\Study\PythonProjects\trash\football_stats_scraper\common\utils.py", line 28, in write_stats_to_database
    (match.DATE, match.HOME, match.AWAY, match.STATS['full_time']['Ball Possession'][0], match.STATS['full_time']['Ball Possession'][1], match.STATS['full_time']['Total shots'][0], match.STATS['full_time']['Total shots'][1], match.STATS['full_time']['Shots on target'][0], match.STATS['full_time']['Shots on target'][1], match.STATS['full_time']['Big Chances'][0], match.STATS['full_time']['Big Chances'][1]))
                                                                                                                                                                                                                                                                                                                                 ~~~~~~~~~~~~~~~~~~~~~~~~^^^^^^^^^^^^^^^
KeyError: 'Big Chances'
2025-09-18 20:34:15,193 - ERROR - Fail at 239: https://www.flashscore.com/match/football/bayern-munich-nVp0wiqd/bochum-8Y2m6ADe/?mid=WQadeyWO
Traceback (most recent call last):
  File "c:\Users\GPbl3YH\Desktop\Study\PythonProjects\trash\football_stats_scraper\main.py", line 27, in <module>
    write_stats_to_database(m, conn)
  File "c:\Users\GPbl3YH\Desktop\Study\PythonProjects\trash\football_stats_scraper\common\utils.py", line 28, in write_stats_to_database
    (match.DATE, match.HOME, match.AWAY, match.STATS['full_time']['Ball Possession'][0], match.STATS['full_time']['Ball Possession'][1], match.STATS['full_time']['Total shots'][0], match.STATS['full_time']['Total shots'][1], match.STATS['full_time']['Shots on target'][0], match.STATS['full_time']['Shots on target'][1], match.STATS['full_time']['Big Chances'][0], match.STATS['full_time']['Big Chances'][1]))
                                                                                                                                                                                                                                                                                                                                 ~~~~~~~~~~~~~~~~~~~~~~~~^^^^^^^^^^^^^^^
KeyError: 'Big Chances'
2025-09-18 20:34:49,840 - ERROR - Fail at 240: https://www.flashscore.com/match/football/bayer-leverkusen-4jcj2zMd/werder-bremen-Ig1f1fy3/?mid=MiACepQ7
Traceback (most recent call last):
  File "c:\Users\GPbl3YH\Desktop\Study\PythonProjects\trash\football_stats_scraper\main.py", line 27, in <module>
    write_stats_to_database(m, conn)
  File "c:\Users\GPbl3YH\Desktop\Study\PythonProjects\trash\football_stats_scraper\common\utils.py", line 28, in write_stats_to_database
    (match.DATE, match.HOME, match.AWAY, match.STATS['full_time']['Ball Possession'][0], match.STATS['full_time']['Ball Possession'][1], match.STATS['full_time']['Total shots'][0], match.STATS['full_time']['Total shots'][1], match.STATS['full_time']['Shots on target'][0], match.STATS['full_time']['Shots on target'][1], match.STATS['full_time']['Big Chances'][0], match.STATS['full_time']['Big Chances'][1]))
                                                                                                                                                                                                                                                                                                                                 ~~~~~~~~~~~~~~~~~~~~~~~~^^^^^^^^^^^^^^^
KeyError: 'Big Chances'
2025-09-18 20:35:25,619 - ERROR - Fail at 241: https://www.flashscore.com/match/football/augsburg-fTVNku3I/dortmund-nP1i5US1/?mid=x0haJmIE
Traceback (most recent call last):
  File "c:\Users\GPbl3YH\Desktop\Study\PythonProjects\trash\football_stats_scraper\main.py", line 27, in <module>
    write_stats_to_database(m, conn)
  File "c:\Users\GPbl3YH\Desktop\Study\PythonProjects\trash\football_stats_scraper\common\utils.py", line 28, in write_stats_to_database
    (match.DATE, match.HOME, match.AWAY, match.STATS['full_time']['Ball Possession'][0], match.STATS['full_time']['Ball Possession'][1], match.STATS['full_time']['Total shots'][0], match.STATS['full_time']['Total shots'][1], match.STATS['full_time']['Shots on target'][0], match.STATS['full_time']['Shots on target'][1], match.STATS['full_time']['Big Chances'][0], match.STATS['full_time']['Big Chances'][1]))
                                                                                                                                                                                                                                                                                                                                 ~~~~~~~~~~~~~~~~~~~~~~~~^^^^^^^^^^^^^^^
KeyError: 'Big Chances'
2025-09-18 20:36:01,069 - ERROR - Fail at 242: https://www.flashscore.com/match/football/freiburg-fiEQZ7C7/rb-leipzig-KbS1suSm/?mid=ELNeaSQr
Traceback (most recent call last):
  File "c:\Users\GPbl3YH\Desktop\Study\PythonProjects\trash\football_stats_scraper\main.py", line 27, in <module>
    write_stats_to_database(m, conn)
  File "c:\Users\GPbl3YH\Desktop\Study\PythonProjects\trash\football_stats_scraper\common\utils.py", line 28, in write_stats_to_database
    (match.DATE, match.HOME, match.AWAY, match.STATS['full_time']['Ball Possession'][0], match.STATS['full_time']['Ball Possession'][1], match.STATS['full_time']['Total shots'][0], match.STATS['full_time']['Total shots'][1], match.STATS['full_time']['Shots on target'][0], match.STATS['full_time']['Shots on target'][1], match.STATS['full_time']['Big Chances'][0], match.STATS['full_time']['Big Chances'][1]))
                                                                                                                                                                                                                                                                                                                                 ~~~~~~~~~~~~~~~~~~~~~~~~^^^^^^^^^^^^^^^
KeyError: 'Big Chances'
2025-09-18 20:36:38,694 - ERROR - Fail at 243: https://www.flashscore.com/match/football/st-pauli-ILyJuN3g/wolfsburg-nwkTahLL/?mid=Mku6FvHt
Traceback (most recent call last):
  File "c:\Users\GPbl3YH\Desktop\Study\PythonProjects\trash\football_stats_scraper\main.py", line 27, in <module>
    write_stats_to_database(m, conn)
  File "c:\Users\GPbl3YH\Desktop\Study\PythonProjects\trash\football_stats_scraper\common\utils.py", line 28, in write_stats_to_database
    (match.DATE, match.HOME, match.AWAY, match.STATS['full_time']['Ball Possession'][0], match.STATS['full_time']['Ball Possession'][1], match.STATS['full_time']['Total shots'][0], match.STATS['full_time']['Total shots'][1], match.STATS['full_time']['Shots on target'][0], match.STATS['full_time']['Shots on target'][1], match.STATS['full_time']['Big Chances'][0], match.STATS['full_time']['Big Chances'][1]))
                                                                                                                                                                                                                                                                                                                                 ~~~~~~~~~~~~~~~~~~~~~~~~^^^^^^^^^^^^^^^
KeyError: 'Big Chances'
2025-09-18 20:37:15,607 - ERROR - Fail at 244: https://www.flashscore.com/match/football/holstein-kiel-63WsD2ei/vfb-stuttgart-nJQmYp1B/?mid=rwXP4l3L
Traceback (most recent call last):
  File "c:\Users\GPbl3YH\Desktop\Study\PythonProjects\trash\football_stats_scraper\main.py", line 27, in <module>
    write_stats_to_database(m, conn)
  File "c:\Users\GPbl3YH\Desktop\Study\PythonProjects\trash\football_stats_scraper\common\utils.py", line 28, in write_stats_to_database
    (match.DATE, match.HOME, match.AWAY, match.STATS['full_time']['Ball Possession'][0], match.STATS['full_time']['Ball Possession'][1], match.STATS['full_time']['Total shots'][0], match.STATS['full_time']['Total shots'][1], match.STATS['full_time']['Shots on target'][0], match.STATS['full_time']['Shots on target'][1], match.STATS['full_time']['Big Chances'][0], match.STATS['full_time']['Big Chances'][1]))
                                                                                                                                                                                                                                                                                                                                 ~~~~~~~~~~~~~~~~~~~~~~~~^^^^^^^^^^^^^^^
KeyError: 'Big Chances'
2025-09-18 20:37:50,764 - ERROR - Fail at 245: https://www.flashscore.com/match/football/b-monchengladbach-88HSzjDr/mainz-EuakNmc1/?mid=4E8uaJWa
Traceback (most recent call last):
  File "c:\Users\GPbl3YH\Desktop\Study\PythonProjects\trash\football_stats_scraper\main.py", line 27, in <module>
    write_stats_to_database(m, conn)
  File "c:\Users\GPbl3YH\Desktop\Study\PythonProjects\trash\football_stats_scraper\common\utils.py", line 28, in write_stats_to_database
    (match.DATE, match.HOME, match.AWAY, match.STATS['full_time']['Ball Possession'][0], match.STATS['full_time']['Ball Possession'][1], match.STATS['full_time']['Total shots'][0], match.STATS['full_time']['Total shots'][1], match.STATS['full_time']['Shots on target'][0], match.STATS['full_time']['Shots on target'][1], match.STATS['full_time']['Big Chances'][0], match.STATS['full_time']['Big Chances'][1]))
                                                                                                                                                                                                                                                                                                                                 ~~~~~~~~~~~~~~~~~~~~~~~~^^^^^^^^^^^^^^^
KeyError: 'Big Chances'
2025-09-18 20:38:27,909 - ERROR - Fail at 246: https://www.flashscore.com/match/football/werder-bremen-Ig1f1fy3/wolfsburg-nwkTahLL/?mid=rPiijklS
Traceback (most recent call last):
  File "c:\Users\GPbl3YH\Desktop\Study\PythonProjects\trash\football_stats_scraper\main.py", line 27, in <module>
    write_stats_to_database(m, conn)
  File "c:\Users\GPbl3YH\Desktop\Study\PythonProjects\trash\football_stats_scraper\common\utils.py", line 28, in write_stats_to_database
    (match.DATE, match.HOME, match.AWAY, match.STATS['full_time']['Ball Possession'][0], match.STATS['full_time']['Ball Possession'][1], match.STATS['full_time']['Total shots'][0], match.STATS['full_time']['Total shots'][1], match.STATS['full_time']['Shots on target'][0], match.STATS['full_time']['Shots on target'][1], match.STATS['full_time']['Big Chances'][0], match.STATS['full_time']['Big Chances'][1]))
                                                                                                                                                                                                                                                                                                                                 ~~~~~~~~~~~~~~~~~~~~~~~~^^^^^^^^^^^^^^^
KeyError: 'Big Chances'
2025-09-18 20:39:02,443 - ERROR - Fail at 247: https://www.flashscore.com/match/football/holstein-kiel-63WsD2ei/union-berlin-pzHW4oaE/?mid=nBwH6AY8
Traceback (most recent call last):
  File "c:\Users\GPbl3YH\Desktop\Study\PythonProjects\trash\football_stats_scraper\main.py", line 27, in <module>
    write_stats_to_database(m, conn)
  File "c:\Users\GPbl3YH\Desktop\Study\PythonProjects\trash\football_stats_scraper\common\utils.py", line 28, in write_stats_to_database
    (match.DATE, match.HOME, match.AWAY, match.STATS['full_time']['Ball Possession'][0], match.STATS['full_time']['Ball Possession'][1], match.STATS['full_time']['Total shots'][0], match.STATS['full_time']['Total shots'][1], match.STATS['full_time']['Shots on target'][0], match.STATS['full_time']['Shots on target'][1], match.STATS['full_time']['Big Chances'][0], match.STATS['full_time']['Big Chances'][1]))
                                                                                                                                                                                                                                                                                                                                 ~~~~~~~~~~~~~~~~~~~~~~~~^^^^^^^^^^^^^^^
KeyError: 'Big Chances'
2025-09-18 20:39:38,004 - ERROR - Fail at 248: https://www.flashscore.com/match/football/bayern-munich-nVp0wiqd/vfb-stuttgart-nJQmYp1B/?mid=2mcmYkSq
Traceback (most recent call last):
  File "c:\Users\GPbl3YH\Desktop\Study\PythonProjects\trash\football_stats_scraper\main.py", line 27, in <module>
    write_stats_to_database(m, conn)
  File "c:\Users\GPbl3YH\Desktop\Study\PythonProjects\trash\football_stats_scraper\common\utils.py", line 28, in write_stats_to_database
    (match.DATE, match.HOME, match.AWAY, match.STATS['full_time']['Ball Possession'][0], match.STATS['full_time']['Ball Possession'][1], match.STATS['full_time']['Total shots'][0], match.STATS['full_time']['Total shots'][1], match.STATS['full_time']['Shots on target'][0], match.STATS['full_time']['Shots on target'][1], match.STATS['full_time']['Big Chances'][0], match.STATS['full_time']['Big Chances'][1]))
                                                                                                                                                                                                                                                                                                                                 ~~~~~~~~~~~~~~~~~~~~~~~~^^^^^^^^^^^^^^^
KeyError: 'Big Chances'
2025-09-18 20:40:12,795 - ERROR - Fail at 249: https://www.flashscore.com/match/football/b-monchengladbach-88HSzjDr/heidenheim-KWixEVWi/?mid=fHjVr7t2
Traceback (most recent call last):
  File "c:\Users\GPbl3YH\Desktop\Study\PythonProjects\trash\football_stats_scraper\main.py", line 27, in <module>
    write_stats_to_database(m, conn)
  File "c:\Users\GPbl3YH\Desktop\Study\PythonProjects\trash\football_stats_scraper\common\utils.py", line 28, in write_stats_to_database
    (match.DATE, match.HOME, match.AWAY, match.STATS['full_time']['Ball Possession'][0], match.STATS['full_time']['Ball Possession'][1], match.STATS['full_time']['Total shots'][0], match.STATS['full_time']['Total shots'][1], match.STATS['full_time']['Shots on target'][0], match.STATS['full_time']['Shots on target'][1], match.STATS['full_time']['Big Chances'][0], match.STATS['full_time']['Big Chances'][1]))
                                                                                                                                                                                                                                                                                                                                 ~~~~~~~~~~~~~~~~~~~~~~~~^^^^^^^^^^^^^^^
KeyError: 'Big Chances'
2025-09-18 20:40:48,103 - ERROR - Fail at 250: https://www.flashscore.com/match/football/bayer-leverkusen-4jcj2zMd/eintracht-frankfurt-8vndvXTk/?mid=r3GGwC4M
Traceback (most recent call last):
  File "c:\Users\GPbl3YH\Desktop\Study\PythonProjects\trash\football_stats_scraper\main.py", line 27, in <module>
    write_stats_to_database(m, conn)
  File "c:\Users\GPbl3YH\Desktop\Study\PythonProjects\trash\football_stats_scraper\common\utils.py", line 28, in write_stats_to_database
    (match.DATE, match.HOME, match.AWAY, match.STATS['full_time']['Ball Possession'][0], match.STATS['full_time']['Ball Possession'][1], match.STATS['full_time']['Total shots'][0], match.STATS['full_time']['Total shots'][1], match.STATS['full_time']['Shots on target'][0], match.STATS['full_time']['Shots on target'][1], match.STATS['full_time']['Big Chances'][0], match.STATS['full_time']['Big Chances'][1]))
                                                                                                                                                                                                                                                                                                                                 ~~~~~~~~~~~~~~~~~~~~~~~~^^^^^^^^^^^^^^^
KeyError: 'Big Chances'
2025-09-18 20:41:24,154 - ERROR - Fail at 251: https://www.flashscore.com/match/football/augsburg-fTVNku3I/freiburg-fiEQZ7C7/?mid=M93rhBJF
Traceback (most recent call last):
  File "c:\Users\GPbl3YH\Desktop\Study\PythonProjects\trash\football_stats_scraper\main.py", line 27, in <module>
    write_stats_to_database(m, conn)
  File "c:\Users\GPbl3YH\Desktop\Study\PythonProjects\trash\football_stats_scraper\common\utils.py", line 28, in write_stats_to_database
    (match.DATE, match.HOME, match.AWAY, match.STATS['full_time']['Ball Possession'][0], match.STATS['full_time']['Ball Possession'][1], match.STATS['full_time']['Total shots'][0], match.STATS['full_time']['Total shots'][1], match.STATS['full_time']['Shots on target'][0], match.STATS['full_time']['Shots on target'][1], match.STATS['full_time']['Big Chances'][0], match.STATS['full_time']['Big Chances'][1]))
                                                                                                                                                                                                                                                                                                                                 ~~~~~~~~~~~~~~~~~~~~~~~~^^^^^^^^^^^^^^^
KeyError: 'Big Chances'
2025-09-18 20:41:59,587 - ERROR - Fail at 252: https://www.flashscore.com/match/football/bochum-8Y2m6ADe/hoffenheim-hQAtP9Sl/?mid=Eq0zfXl3
Traceback (most recent call last):
  File "c:\Users\GPbl3YH\Desktop\Study\PythonProjects\trash\football_stats_scraper\main.py", line 27, in <module>
    write_stats_to_database(m, conn)
  File "c:\Users\GPbl3YH\Desktop\Study\PythonProjects\trash\football_stats_scraper\common\utils.py", line 28, in write_stats_to_database
    (match.DATE, match.HOME, match.AWAY, match.STATS['full_time']['Ball Possession'][0], match.STATS['full_time']['Ball Possession'][1], match.STATS['full_time']['Total shots'][0], match.STATS['full_time']['Total shots'][1], match.STATS['full_time']['Shots on target'][0], match.STATS['full_time']['Shots on target'][1], match.STATS['full_time']['Big Chances'][0], match.STATS['full_time']['Big Chances'][1]))
                                                                                                                                                                                                                                                                                                                                 ~~~~~~~~~~~~~~~~~~~~~~~~^^^^^^^^^^^^^^^
KeyError: 'Big Chances'
2025-09-18 20:42:35,046 - ERROR - Fail at 253: https://www.flashscore.com/match/football/mainz-EuakNmc1/rb-leipzig-KbS1suSm/?mid=E7rNpTBk
Traceback (most recent call last):
  File "c:\Users\GPbl3YH\Desktop\Study\PythonProjects\trash\football_stats_scraper\main.py", line 27, in <module>
    write_stats_to_database(m, conn)
  File "c:\Users\GPbl3YH\Desktop\Study\PythonProjects\trash\football_stats_scraper\common\utils.py", line 28, in write_stats_to_database
    (match.DATE, match.HOME, match.AWAY, match.STATS['full_time']['Ball Possession'][0], match.STATS['full_time']['Ball Possession'][1], match.STATS['full_time']['Total shots'][0], match.STATS['full_time']['Total shots'][1], match.STATS['full_time']['Shots on target'][0], match.STATS['full_time']['Shots on target'][1], match.STATS['full_time']['Big Chances'][0], match.STATS['full_time']['Big Chances'][1]))
                                                                                                                                                                                                                                                                                                                                 ~~~~~~~~~~~~~~~~~~~~~~~~^^^^^^^^^^^^^^^
KeyError: 'Big Chances'
2025-09-18 20:43:10,596 - ERROR - Fail at 254: https://www.flashscore.com/match/football/dortmund-nP1i5US1/st-pauli-ILyJuN3g/?mid=z1eeWTdd
Traceback (most recent call last):
  File "c:\Users\GPbl3YH\Desktop\Study\PythonProjects\trash\football_stats_scraper\main.py", line 27, in <module>
    write_stats_to_database(m, conn)
  File "c:\Users\GPbl3YH\Desktop\Study\PythonProjects\trash\football_stats_scraper\common\utils.py", line 28, in write_stats_to_database
    (match.DATE, match.HOME, match.AWAY, match.STATS['full_time']['Ball Possession'][0], match.STATS['full_time']['Ball Possession'][1], match.STATS['full_time']['Total shots'][0], match.STATS['full_time']['Total shots'][1], match.STATS['full_time']['Shots on target'][0], match.STATS['full_time']['Shots on target'][1], match.STATS['full_time']['Big Chances'][0], match.STATS['full_time']['Big Chances'][1]))
                                                                                                                                                                                                                                                                                                                                 ~~~~~~~~~~~~~~~~~~~~~~~~^^^^^^^^^^^^^^^
KeyError: 'Big Chances'
2025-09-18 20:43:47,743 - ERROR - Fail at 255: https://www.flashscore.com/match/football/hoffenheim-hQAtP9Sl/vfb-stuttgart-nJQmYp1B/?mid=nc8W6DTp
Traceback (most recent call last):
  File "c:\Users\GPbl3YH\Desktop\Study\PythonProjects\trash\football_stats_scraper\main.py", line 27, in <module>
    write_stats_to_database(m, conn)
  File "c:\Users\GPbl3YH\Desktop\Study\PythonProjects\trash\football_stats_scraper\common\utils.py", line 28, in write_stats_to_database
    (match.DATE, match.HOME, match.AWAY, match.STATS['full_time']['Ball Possession'][0], match.STATS['full_time']['Ball Possession'][1], match.STATS['full_time']['Total shots'][0], match.STATS['full_time']['Total shots'][1], match.STATS['full_time']['Shots on target'][0], match.STATS['full_time']['Shots on target'][1], match.STATS['full_time']['Big Chances'][0], match.STATS['full_time']['Big Chances'][1]))
                                                                                                                                                                                                                                                                                                                                 ~~~~~~~~~~~~~~~~~~~~~~~~^^^^^^^^^^^^^^^
KeyError: 'Big Chances'
2025-09-18 20:44:22,801 - ERROR - Fail at 256: https://www.flashscore.com/match/football/bayern-munich-nVp0wiqd/eintracht-frankfurt-8vndvXTk/?mid=ShoJUGLi
Traceback (most recent call last):
  File "c:\Users\GPbl3YH\Desktop\Study\PythonProjects\trash\football_stats_scraper\main.py", line 27, in <module>
    write_stats_to_database(m, conn)
  File "c:\Users\GPbl3YH\Desktop\Study\PythonProjects\trash\football_stats_scraper\common\utils.py", line 28, in write_stats_to_database
    (match.DATE, match.HOME, match.AWAY, match.STATS['full_time']['Ball Possession'][0], match.STATS['full_time']['Ball Possession'][1], match.STATS['full_time']['Total shots'][0], match.STATS['full_time']['Total shots'][1], match.STATS['full_time']['Shots on target'][0], match.STATS['full_time']['Shots on target'][1], match.STATS['full_time']['Big Chances'][0], match.STATS['full_time']['Big Chances'][1]))
                                                                                                                                                                                                                                                                                                                                 ~~~~~~~~~~~~~~~~~~~~~~~~^^^^^^^^^^^^^^^
KeyError: 'Big Chances'
2025-09-18 20:44:57,919 - ERROR - Fail at 257: https://www.flashscore.com/match/football/heidenheim-KWixEVWi/rb-leipzig-KbS1suSm/?mid=0KbQSfj4
Traceback (most recent call last):
  File "c:\Users\GPbl3YH\Desktop\Study\PythonProjects\trash\football_stats_scraper\main.py", line 27, in <module>
    write_stats_to_database(m, conn)
  File "c:\Users\GPbl3YH\Desktop\Study\PythonProjects\trash\football_stats_scraper\common\utils.py", line 28, in write_stats_to_database
    (match.DATE, match.HOME, match.AWAY, match.STATS['full_time']['Ball Possession'][0], match.STATS['full_time']['Ball Possession'][1], match.STATS['full_time']['Total shots'][0], match.STATS['full_time']['Total shots'][1], match.STATS['full_time']['Shots on target'][0], match.STATS['full_time']['Shots on target'][1], match.STATS['full_time']['Big Chances'][0], match.STATS['full_time']['Big Chances'][1]))
                                                                                                                                                                                                                                                                                                                                 ~~~~~~~~~~~~~~~~~~~~~~~~^^^^^^^^^^^^^^^
KeyError: 'Big Chances'
2025-09-18 20:45:32,203 - ERROR - Fail at 258: https://www.flashscore.com/match/football/mainz-EuakNmc1/st-pauli-ILyJuN3g/?mid=zwD8uYZ9
Traceback (most recent call last):
  File "c:\Users\GPbl3YH\Desktop\Study\PythonProjects\trash\football_stats_scraper\main.py", line 27, in <module>
    write_stats_to_database(m, conn)
  File "c:\Users\GPbl3YH\Desktop\Study\PythonProjects\trash\football_stats_scraper\common\utils.py", line 28, in write_stats_to_database
    (match.DATE, match.HOME, match.AWAY, match.STATS['full_time']['Ball Possession'][0], match.STATS['full_time']['Ball Possession'][1], match.STATS['full_time']['Total shots'][0], match.STATS['full_time']['Total shots'][1], match.STATS['full_time']['Shots on target'][0], match.STATS['full_time']['Shots on target'][1], match.STATS['full_time']['Big Chances'][0], match.STATS['full_time']['Big Chances'][1]))
                                                                                                                                                                                                                                                                                                                                 ~~~~~~~~~~~~~~~~~~~~~~~~^^^^^^^^^^^^^^^
KeyError: 'Big Chances'
2025-09-18 20:46:12,180 - ERROR - Fail at 259: https://www.flashscore.com/match/football/bayer-leverkusen-4jcj2zMd/holstein-kiel-63WsD2ei/?mid=tbtaPLqC
Traceback (most recent call last):
  File "c:\Users\GPbl3YH\Desktop\Study\PythonProjects\trash\football_stats_scraper\main.py", line 27, in <module>
    write_stats_to_database(m, conn)
  File "c:\Users\GPbl3YH\Desktop\Study\PythonProjects\trash\football_stats_scraper\common\utils.py", line 28, in write_stats_to_database
    (match.DATE, match.HOME, match.AWAY, match.STATS['full_time']['Ball Possession'][0], match.STATS['full_time']['Ball Possession'][1], match.STATS['full_time']['Total shots'][0], match.STATS['full_time']['Total shots'][1], match.STATS['full_time']['Shots on target'][0], match.STATS['full_time']['Shots on target'][1], match.STATS['full_time']['Big Chances'][0], match.STATS['full_time']['Big Chances'][1]))
                                                                                                                                                                                                                                                                                                                                 ~~~~~~~~~~~~~~~~~~~~~~~~^^^^^^^^^^^^^^^
KeyError: 'Big Chances'
2025-09-18 20:46:46,409 - ERROR - Fail at 260: https://www.flashscore.com/match/football/bochum-8Y2m6ADe/wolfsburg-nwkTahLL/?mid=ENOasf5c
Traceback (most recent call last):
  File "c:\Users\GPbl3YH\Desktop\Study\PythonProjects\trash\football_stats_scraper\main.py", line 27, in <module>
    write_stats_to_database(m, conn)
  File "c:\Users\GPbl3YH\Desktop\Study\PythonProjects\trash\football_stats_scraper\common\utils.py", line 28, in write_stats_to_database
    (match.DATE, match.HOME, match.AWAY, match.STATS['full_time']['Ball Possession'][0], match.STATS['full_time']['Ball Possession'][1], match.STATS['full_time']['Total shots'][0], match.STATS['full_time']['Total shots'][1], match.STATS['full_time']['Shots on target'][0], match.STATS['full_time']['Shots on target'][1], match.STATS['full_time']['Big Chances'][0], match.STATS['full_time']['Big Chances'][1]))
                                                                                                                                                                                                                                                                                                                                 ~~~~~~~~~~~~~~~~~~~~~~~~^^^^^^^^^^^^^^^
KeyError: 'Big Chances'
2025-09-18 20:47:21,571 - ERROR - Fail at 261: https://www.flashscore.com/match/football/dortmund-nP1i5US1/union-berlin-pzHW4oaE/?mid=lpXDJjDj
Traceback (most recent call last):
  File "c:\Users\GPbl3YH\Desktop\Study\PythonProjects\trash\football_stats_scraper\main.py", line 27, in <module>
    write_stats_to_database(m, conn)
  File "c:\Users\GPbl3YH\Desktop\Study\PythonProjects\trash\football_stats_scraper\common\utils.py", line 28, in write_stats_to_database
    (match.DATE, match.HOME, match.AWAY, match.STATS['full_time']['Ball Possession'][0], match.STATS['full_time']['Ball Possession'][1], match.STATS['full_time']['Total shots'][0], match.STATS['full_time']['Total shots'][1], match.STATS['full_time']['Shots on target'][0], match.STATS['full_time']['Shots on target'][1], match.STATS['full_time']['Big Chances'][0], match.STATS['full_time']['Big Chances'][1]))
                                                                                                                                                                                                                                                                                                                                 ~~~~~~~~~~~~~~~~~~~~~~~~^^^^^^^^^^^^^^^
KeyError: 'Big Chances'
2025-09-18 20:47:55,773 - ERROR - Fail at 262: https://www.flashscore.com/match/football/freiburg-fiEQZ7C7/werder-bremen-Ig1f1fy3/?mid=dnhZQYKG
Traceback (most recent call last):
  File "c:\Users\GPbl3YH\Desktop\Study\PythonProjects\trash\football_stats_scraper\main.py", line 27, in <module>
    write_stats_to_database(m, conn)
  File "c:\Users\GPbl3YH\Desktop\Study\PythonProjects\trash\football_stats_scraper\common\utils.py", line 28, in write_stats_to_database
    (match.DATE, match.HOME, match.AWAY, match.STATS['full_time']['Ball Possession'][0], match.STATS['full_time']['Ball Possession'][1], match.STATS['full_time']['Total shots'][0], match.STATS['full_time']['Total shots'][1], match.STATS['full_time']['Shots on target'][0], match.STATS['full_time']['Shots on target'][1], match.STATS['full_time']['Big Chances'][0], match.STATS['full_time']['Big Chances'][1]))
                                                                                                                                                                                                                                                                                                                                 ~~~~~~~~~~~~~~~~~~~~~~~~^^^^^^^^^^^^^^^
KeyError: 'Big Chances'
2025-09-18 20:48:30,824 - ERROR - Fail at 263: https://www.flashscore.com/match/football/augsburg-fTVNku3I/b-monchengladbach-88HSzjDr/?mid=UajsPCkT
Traceback (most recent call last):
  File "c:\Users\GPbl3YH\Desktop\Study\PythonProjects\trash\football_stats_scraper\main.py", line 27, in <module>
    write_stats_to_database(m, conn)
  File "c:\Users\GPbl3YH\Desktop\Study\PythonProjects\trash\football_stats_scraper\common\utils.py", line 28, in write_stats_to_database
    (match.DATE, match.HOME, match.AWAY, match.STATS['full_time']['Ball Possession'][0], match.STATS['full_time']['Ball Possession'][1], match.STATS['full_time']['Total shots'][0], match.STATS['full_time']['Total shots'][1], match.STATS['full_time']['Shots on target'][0], match.STATS['full_time']['Shots on target'][1], match.STATS['full_time']['Big Chances'][0], match.STATS['full_time']['Big Chances'][1]))
                                                                                                                                                                                                                                                                                                                                 ~~~~~~~~~~~~~~~~~~~~~~~~^^^^^^^^^^^^^^^
KeyError: 'Big Chances'
2025-09-18 20:49:05,664 - ERROR - Fail at 264: https://www.flashscore.com/match/football/hoffenheim-hQAtP9Sl/werder-bremen-Ig1f1fy3/?mid=bFO8E4Vg
Traceback (most recent call last):
  File "c:\Users\GPbl3YH\Desktop\Study\PythonProjects\trash\football_stats_scraper\main.py", line 27, in <module>
    write_stats_to_database(m, conn)
  File "c:\Users\GPbl3YH\Desktop\Study\PythonProjects\trash\football_stats_scraper\common\utils.py", line 28, in write_stats_to_database
    (match.DATE, match.HOME, match.AWAY, match.STATS['full_time']['Ball Possession'][0], match.STATS['full_time']['Ball Possession'][1], match.STATS['full_time']['Total shots'][0], match.STATS['full_time']['Total shots'][1], match.STATS['full_time']['Shots on target'][0], match.STATS['full_time']['Shots on target'][1], match.STATS['full_time']['Big Chances'][0], match.STATS['full_time']['Big Chances'][1]))
                                                                                                                                                                                                                                                                                                                                 ~~~~~~~~~~~~~~~~~~~~~~~~^^^^^^^^^^^^^^^
KeyError: 'Big Chances'
2025-09-18 20:49:40,763 - ERROR - Fail at 265: https://www.flashscore.com/match/football/eintracht-frankfurt-8vndvXTk/holstein-kiel-63WsD2ei/?mid=pWnjRsFa
Traceback (most recent call last):
  File "c:\Users\GPbl3YH\Desktop\Study\PythonProjects\trash\football_stats_scraper\main.py", line 27, in <module>
    write_stats_to_database(m, conn)
  File "c:\Users\GPbl3YH\Desktop\Study\PythonProjects\trash\football_stats_scraper\common\utils.py", line 28, in write_stats_to_database
    (match.DATE, match.HOME, match.AWAY, match.STATS['full_time']['Ball Possession'][0], match.STATS['full_time']['Ball Possession'][1], match.STATS['full_time']['Total shots'][0], match.STATS['full_time']['Total shots'][1], match.STATS['full_time']['Shots on target'][0], match.STATS['full_time']['Shots on target'][1], match.STATS['full_time']['Big Chances'][0], match.STATS['full_time']['Big Chances'][1]))
                                                                                                                                                                                                                                                                                                                                 ~~~~~~~~~~~~~~~~~~~~~~~~^^^^^^^^^^^^^^^
KeyError: 'Big Chances'
2025-09-18 20:50:15,229 - ERROR - Fail at 266: https://www.flashscore.com/match/football/bayer-leverkusen-4jcj2zMd/bayern-munich-nVp0wiqd/?mid=IukqGdk1
Traceback (most recent call last):
  File "c:\Users\GPbl3YH\Desktop\Study\PythonProjects\trash\football_stats_scraper\main.py", line 27, in <module>
    write_stats_to_database(m, conn)
  File "c:\Users\GPbl3YH\Desktop\Study\PythonProjects\trash\football_stats_scraper\common\utils.py", line 28, in write_stats_to_database
    (match.DATE, match.HOME, match.AWAY, match.STATS['full_time']['Ball Possession'][0], match.STATS['full_time']['Ball Possession'][1], match.STATS['full_time']['Total shots'][0], match.STATS['full_time']['Total shots'][1], match.STATS['full_time']['Shots on target'][0], match.STATS['full_time']['Shots on target'][1], match.STATS['full_time']['Big Chances'][0], match.STATS['full_time']['Big Chances'][1]))
                                                                                                                                                                                                                                                                                                                                 ~~~~~~~~~~~~~~~~~~~~~~~~^^^^^^^^^^^^^^^
KeyError: 'Big Chances'
2025-09-18 20:50:50,334 - ERROR - Fail at 267: https://www.flashscore.com/match/football/b-monchengladbach-88HSzjDr/union-berlin-pzHW4oaE/?mid=CIlrT3pm
Traceback (most recent call last):
  File "c:\Users\GPbl3YH\Desktop\Study\PythonProjects\trash\football_stats_scraper\main.py", line 27, in <module>
    write_stats_to_database(m, conn)
  File "c:\Users\GPbl3YH\Desktop\Study\PythonProjects\trash\football_stats_scraper\common\utils.py", line 28, in write_stats_to_database
    (match.DATE, match.HOME, match.AWAY, match.STATS['full_time']['Ball Possession'][0], match.STATS['full_time']['Ball Possession'][1], match.STATS['full_time']['Total shots'][0], match.STATS['full_time']['Total shots'][1], match.STATS['full_time']['Shots on target'][0], match.STATS['full_time']['Shots on target'][1], match.STATS['full_time']['Big Chances'][0], match.STATS['full_time']['Big Chances'][1]))
                                                                                                                                                                                                                                                                                                                                 ~~~~~~~~~~~~~~~~~~~~~~~~^^^^^^^^^^^^^^^
KeyError: 'Big Chances'
2025-09-18 20:51:25,312 - ERROR - Fail at 268: https://www.flashscore.com/match/football/freiburg-fiEQZ7C7/st-pauli-ILyJuN3g/?mid=6uSGCr06
Traceback (most recent call last):
  File "c:\Users\GPbl3YH\Desktop\Study\PythonProjects\trash\football_stats_scraper\main.py", line 27, in <module>
    write_stats_to_database(m, conn)
  File "c:\Users\GPbl3YH\Desktop\Study\PythonProjects\trash\football_stats_scraper\common\utils.py", line 28, in write_stats_to_database
    (match.DATE, match.HOME, match.AWAY, match.STATS['full_time']['Ball Possession'][0], match.STATS['full_time']['Ball Possession'][1], match.STATS['full_time']['Total shots'][0], match.STATS['full_time']['Total shots'][1], match.STATS['full_time']['Shots on target'][0], match.STATS['full_time']['Shots on target'][1], match.STATS['full_time']['Big Chances'][0], match.STATS['full_time']['Big Chances'][1]))
                                                                                                                                                                                                                                                                                                                                 ~~~~~~~~~~~~~~~~~~~~~~~~^^^^^^^^^^^^^^^
KeyError: 'Big Chances'
2025-09-18 20:52:00,883 - ERROR - Fail at 269: https://www.flashscore.com/match/football/heidenheim-KWixEVWi/mainz-EuakNmc1/?mid=f18BYPMP
Traceback (most recent call last):
  File "c:\Users\GPbl3YH\Desktop\Study\PythonProjects\trash\football_stats_scraper\main.py", line 27, in <module>
    write_stats_to_database(m, conn)
  File "c:\Users\GPbl3YH\Desktop\Study\PythonProjects\trash\football_stats_scraper\common\utils.py", line 28, in write_stats_to_database
    (match.DATE, match.HOME, match.AWAY, match.STATS['full_time']['Ball Possession'][0], match.STATS['full_time']['Ball Possession'][1], match.STATS['full_time']['Total shots'][0], match.STATS['full_time']['Total shots'][1], match.STATS['full_time']['Shots on target'][0], match.STATS['full_time']['Shots on target'][1], match.STATS['full_time']['Big Chances'][0], match.STATS['full_time']['Big Chances'][1]))
                                                                                                                                                                                                                                                                                                                                 ~~~~~~~~~~~~~~~~~~~~~~~~^^^^^^^^^^^^^^^
KeyError: 'Big Chances'
2025-09-18 20:52:35,917 - ERROR - Fail at 270: https://www.flashscore.com/match/football/augsburg-fTVNku3I/rb-leipzig-KbS1suSm/?mid=Q5hiEzKD
Traceback (most recent call last):
  File "c:\Users\GPbl3YH\Desktop\Study\PythonProjects\trash\football_stats_scraper\main.py", line 27, in <module>
    write_stats_to_database(m, conn)
  File "c:\Users\GPbl3YH\Desktop\Study\PythonProjects\trash\football_stats_scraper\common\utils.py", line 28, in write_stats_to_database
    (match.DATE, match.HOME, match.AWAY, match.STATS['full_time']['Ball Possession'][0], match.STATS['full_time']['Ball Possession'][1], match.STATS['full_time']['Total shots'][0], match.STATS['full_time']['Total shots'][1], match.STATS['full_time']['Shots on target'][0], match.STATS['full_time']['Shots on target'][1], match.STATS['full_time']['Big Chances'][0], match.STATS['full_time']['Big Chances'][1]))
                                                                                                                                                                                                                                                                                                                                 ~~~~~~~~~~~~~~~~~~~~~~~~^^^^^^^^^^^^^^^
KeyError: 'Big Chances'
2025-09-18 20:53:10,309 - ERROR - Fail at 271: https://www.flashscore.com/match/football/vfb-stuttgart-nJQmYp1B/wolfsburg-nwkTahLL/?mid=SfGPAMUI
Traceback (most recent call last):
  File "c:\Users\GPbl3YH\Desktop\Study\PythonProjects\trash\football_stats_scraper\main.py", line 27, in <module>
    write_stats_to_database(m, conn)
  File "c:\Users\GPbl3YH\Desktop\Study\PythonProjects\trash\football_stats_scraper\common\utils.py", line 28, in write_stats_to_database
    (match.DATE, match.HOME, match.AWAY, match.STATS['full_time']['Ball Possession'][0], match.STATS['full_time']['Ball Possession'][1], match.STATS['full_time']['Total shots'][0], match.STATS['full_time']['Total shots'][1], match.STATS['full_time']['Shots on target'][0], match.STATS['full_time']['Shots on target'][1], match.STATS['full_time']['Big Chances'][0], match.STATS['full_time']['Big Chances'][1]))
                                                                                                                                                                                                                                                                                                                                 ~~~~~~~~~~~~~~~~~~~~~~~~^^^^^^^^^^^^^^^
KeyError: 'Big Chances'
2025-09-18 20:53:44,572 - ERROR - Fail at 272: https://www.flashscore.com/match/football/bochum-8Y2m6ADe/dortmund-nP1i5US1/?mid=rsNyMnwK
Traceback (most recent call last):
  File "c:\Users\GPbl3YH\Desktop\Study\PythonProjects\trash\football_stats_scraper\main.py", line 27, in <module>
    write_stats_to_database(m, conn)
  File "c:\Users\GPbl3YH\Desktop\Study\PythonProjects\trash\football_stats_scraper\common\utils.py", line 28, in write_stats_to_database
    (match.DATE, match.HOME, match.AWAY, match.STATS['full_time']['Ball Possession'][0], match.STATS['full_time']['Ball Possession'][1], match.STATS['full_time']['Total shots'][0], match.STATS['full_time']['Total shots'][1], match.STATS['full_time']['Shots on target'][0], match.STATS['full_time']['Shots on target'][1], match.STATS['full_time']['Big Chances'][0], match.STATS['full_time']['Big Chances'][1]))
                                                                                                                                                                                                                                                                                                                                 ~~~~~~~~~~~~~~~~~~~~~~~~^^^^^^^^^^^^^^^
KeyError: 'Big Chances'
2025-09-18 20:54:19,390 - ERROR - Fail at 273: https://www.flashscore.com/match/football/rb-leipzig-KbS1suSm/st-pauli-ILyJuN3g/?mid=dQ0zIIKl
Traceback (most recent call last):
  File "c:\Users\GPbl3YH\Desktop\Study\PythonProjects\trash\football_stats_scraper\main.py", line 27, in <module>
    write_stats_to_database(m, conn)
  File "c:\Users\GPbl3YH\Desktop\Study\PythonProjects\trash\football_stats_scraper\common\utils.py", line 28, in write_stats_to_database
    (match.DATE, match.HOME, match.AWAY, match.STATS['full_time']['Ball Possession'][0], match.STATS['full_time']['Ball Possession'][1], match.STATS['full_time']['Total shots'][0], match.STATS['full_time']['Total shots'][1], match.STATS['full_time']['Shots on target'][0], match.STATS['full_time']['Shots on target'][1], match.STATS['full_time']['Big Chances'][0], match.STATS['full_time']['Big Chances'][1]))
                                                                                                                                                                                                                                                                                                                                 ~~~~~~~~~~~~~~~~~~~~~~~~^^^^^^^^^^^^^^^
KeyError: 'Big Chances'
2025-09-18 20:54:54,115 - ERROR - Fail at 274: https://www.flashscore.com/match/football/dortmund-nP1i5US1/vfb-stuttgart-nJQmYp1B/?mid=2k0SlKj2
Traceback (most recent call last):
  File "c:\Users\GPbl3YH\Desktop\Study\PythonProjects\trash\football_stats_scraper\main.py", line 27, in <module>
    write_stats_to_database(m, conn)
  File "c:\Users\GPbl3YH\Desktop\Study\PythonProjects\trash\football_stats_scraper\common\utils.py", line 28, in write_stats_to_database
    (match.DATE, match.HOME, match.AWAY, match.STATS['full_time']['Ball Possession'][0], match.STATS['full_time']['Ball Possession'][1], match.STATS['full_time']['Total shots'][0], match.STATS['full_time']['Total shots'][1], match.STATS['full_time']['Shots on target'][0], match.STATS['full_time']['Shots on target'][1], match.STATS['full_time']['Big Chances'][0], match.STATS['full_time']['Big Chances'][1]))
                                                                                                                                                                                                                                                                                                                                 ~~~~~~~~~~~~~~~~~~~~~~~~^^^^^^^^^^^^^^^
KeyError: 'Big Chances'
2025-09-18 20:55:28,268 - ERROR - Fail at 275: https://www.flashscore.com/match/football/bayer-leverkusen-4jcj2zMd/wolfsburg-nwkTahLL/?mid=Uy2KjtMk
Traceback (most recent call last):
  File "c:\Users\GPbl3YH\Desktop\Study\PythonProjects\trash\football_stats_scraper\main.py", line 27, in <module>
    write_stats_to_database(m, conn)
  File "c:\Users\GPbl3YH\Desktop\Study\PythonProjects\trash\football_stats_scraper\common\utils.py", line 28, in write_stats_to_database
    (match.DATE, match.HOME, match.AWAY, match.STATS['full_time']['Ball Possession'][0], match.STATS['full_time']['Ball Possession'][1], match.STATS['full_time']['Total shots'][0], match.STATS['full_time']['Total shots'][1], match.STATS['full_time']['Shots on target'][0], match.STATS['full_time']['Shots on target'][1], match.STATS['full_time']['Big Chances'][0], match.STATS['full_time']['Big Chances'][1]))
                                                                                                                                                                                                                                                                                                                                 ~~~~~~~~~~~~~~~~~~~~~~~~^^^^^^^^^^^^^^^
KeyError: 'Big Chances'
2025-09-18 20:56:02,925 - ERROR - Fail at 276: https://www.flashscore.com/match/football/b-monchengladbach-88HSzjDr/eintracht-frankfurt-8vndvXTk/?mid=IcrFCNr9
Traceback (most recent call last):
  File "c:\Users\GPbl3YH\Desktop\Study\PythonProjects\trash\football_stats_scraper\main.py", line 27, in <module>
    write_stats_to_database(m, conn)
  File "c:\Users\GPbl3YH\Desktop\Study\PythonProjects\trash\football_stats_scraper\common\utils.py", line 28, in write_stats_to_database
    (match.DATE, match.HOME, match.AWAY, match.STATS['full_time']['Ball Possession'][0], match.STATS['full_time']['Ball Possession'][1], match.STATS['full_time']['Total shots'][0], match.STATS['full_time']['Total shots'][1], match.STATS['full_time']['Shots on target'][0], match.STATS['full_time']['Shots on target'][1], match.STATS['full_time']['Big Chances'][0], match.STATS['full_time']['Big Chances'][1]))
                                                                                                                                                                                                                                                                                                                                 ~~~~~~~~~~~~~~~~~~~~~~~~^^^^^^^^^^^^^^^
KeyError: 'Big Chances'
2025-09-18 20:56:40,618 - ERROR - Fail at 277: https://www.flashscore.com/match/football/bochum-8Y2m6ADe/holstein-kiel-63WsD2ei/?mid=pY1dP0SE
Traceback (most recent call last):
  File "c:\Users\GPbl3YH\Desktop\Study\PythonProjects\trash\football_stats_scraper\main.py", line 27, in <module>
    write_stats_to_database(m, conn)
  File "c:\Users\GPbl3YH\Desktop\Study\PythonProjects\trash\football_stats_scraper\common\utils.py", line 28, in write_stats_to_database
    (match.DATE, match.HOME, match.AWAY, match.STATS['full_time']['Ball Possession'][0], match.STATS['full_time']['Ball Possession'][1], match.STATS['full_time']['Total shots'][0], match.STATS['full_time']['Total shots'][1], match.STATS['full_time']['Shots on target'][0], match.STATS['full_time']['Shots on target'][1], match.STATS['full_time']['Big Chances'][0], match.STATS['full_time']['Big Chances'][1]))
                                                                                                                                                                                                                                                                                                                                 ~~~~~~~~~~~~~~~~~~~~~~~~^^^^^^^^^^^^^^^
KeyError: 'Big Chances'
2025-09-18 20:57:14,736 - ERROR - Fail at 278: https://www.flashscore.com/match/football/freiburg-fiEQZ7C7/heidenheim-KWixEVWi/?mid=QNoNA1DL
Traceback (most recent call last):
  File "c:\Users\GPbl3YH\Desktop\Study\PythonProjects\trash\football_stats_scraper\main.py", line 27, in <module>
    write_stats_to_database(m, conn)
  File "c:\Users\GPbl3YH\Desktop\Study\PythonProjects\trash\football_stats_scraper\common\utils.py", line 28, in write_stats_to_database
    (match.DATE, match.HOME, match.AWAY, match.STATS['full_time']['Ball Possession'][0], match.STATS['full_time']['Ball Possession'][1], match.STATS['full_time']['Total shots'][0], match.STATS['full_time']['Total shots'][1], match.STATS['full_time']['Shots on target'][0], match.STATS['full_time']['Shots on target'][1], match.STATS['full_time']['Big Chances'][0], match.STATS['full_time']['Big Chances'][1]))
                                                                                                                                                                                                                                                                                                                                 ~~~~~~~~~~~~~~~~~~~~~~~~^^^^^^^^^^^^^^^
KeyError: 'Big Chances'
2025-09-18 20:57:48,546 - ERROR - Fail at 279: https://www.flashscore.com/match/football/hoffenheim-hQAtP9Sl/union-berlin-pzHW4oaE/?mid=hvFA1cz8
Traceback (most recent call last):
  File "c:\Users\GPbl3YH\Desktop\Study\PythonProjects\trash\football_stats_scraper\main.py", line 27, in <module>
    write_stats_to_database(m, conn)
  File "c:\Users\GPbl3YH\Desktop\Study\PythonProjects\trash\football_stats_scraper\common\utils.py", line 28, in write_stats_to_database
    (match.DATE, match.HOME, match.AWAY, match.STATS['full_time']['Ball Possession'][0], match.STATS['full_time']['Ball Possession'][1], match.STATS['full_time']['Total shots'][0], match.STATS['full_time']['Total shots'][1], match.STATS['full_time']['Shots on target'][0], match.STATS['full_time']['Shots on target'][1], match.STATS['full_time']['Big Chances'][0], match.STATS['full_time']['Big Chances'][1]))
                                                                                                                                                                                                                                                                                                                                 ~~~~~~~~~~~~~~~~~~~~~~~~^^^^^^^^^^^^^^^
KeyError: 'Big Chances'
2025-09-18 20:58:23,546 - ERROR - Fail at 280: https://www.flashscore.com/match/football/bayern-munich-nVp0wiqd/werder-bremen-Ig1f1fy3/?mid=AeNg5uyq
Traceback (most recent call last):
  File "c:\Users\GPbl3YH\Desktop\Study\PythonProjects\trash\football_stats_scraper\main.py", line 27, in <module>
    write_stats_to_database(m, conn)
  File "c:\Users\GPbl3YH\Desktop\Study\PythonProjects\trash\football_stats_scraper\common\utils.py", line 28, in write_stats_to_database
    (match.DATE, match.HOME, match.AWAY, match.STATS['full_time']['Ball Possession'][0], match.STATS['full_time']['Ball Possession'][1], match.STATS['full_time']['Total shots'][0], match.STATS['full_time']['Total shots'][1], match.STATS['full_time']['Shots on target'][0], match.STATS['full_time']['Shots on target'][1], match.STATS['full_time']['Big Chances'][0], match.STATS['full_time']['Big Chances'][1]))
                                                                                                                                                                                                                                                                                                                                 ~~~~~~~~~~~~~~~~~~~~~~~~^^^^^^^^^^^^^^^
KeyError: 'Big Chances'
2025-09-18 20:59:02,749 - ERROR - Fail at 281: https://www.flashscore.com/match/football/augsburg-fTVNku3I/mainz-EuakNmc1/?mid=dCL13J5e
Traceback (most recent call last):
  File "c:\Users\GPbl3YH\Desktop\Study\PythonProjects\trash\football_stats_scraper\main.py", line 27, in <module>
    write_stats_to_database(m, conn)
  File "c:\Users\GPbl3YH\Desktop\Study\PythonProjects\trash\football_stats_scraper\common\utils.py", line 28, in write_stats_to_database
    (match.DATE, match.HOME, match.AWAY, match.STATS['full_time']['Ball Possession'][0], match.STATS['full_time']['Ball Possession'][1], match.STATS['full_time']['Total shots'][0], match.STATS['full_time']['Total shots'][1], match.STATS['full_time']['Shots on target'][0], match.STATS['full_time']['Shots on target'][1], match.STATS['full_time']['Big Chances'][0], match.STATS['full_time']['Big Chances'][1]))
                                                                                                                                                                                                                                                                                                                                 ~~~~~~~~~~~~~~~~~~~~~~~~^^^^^^^^^^^^^^^
KeyError: 'Big Chances'
2025-09-18 20:59:38,506 - ERROR - Fail at 282: https://www.flashscore.com/match/football/mainz-EuakNmc1/werder-bremen-Ig1f1fy3/?mid=8OhVCWxh
Traceback (most recent call last):
  File "c:\Users\GPbl3YH\Desktop\Study\PythonProjects\trash\football_stats_scraper\main.py", line 27, in <module>
    write_stats_to_database(m, conn)
  File "c:\Users\GPbl3YH\Desktop\Study\PythonProjects\trash\football_stats_scraper\common\utils.py", line 28, in write_stats_to_database
    (match.DATE, match.HOME, match.AWAY, match.STATS['full_time']['Ball Possession'][0], match.STATS['full_time']['Ball Possession'][1], match.STATS['full_time']['Total shots'][0], match.STATS['full_time']['Total shots'][1], match.STATS['full_time']['Shots on target'][0], match.STATS['full_time']['Shots on target'][1], match.STATS['full_time']['Big Chances'][0], match.STATS['full_time']['Big Chances'][1]))
                                                                                                                                                                                                                                                                                                                                 ~~~~~~~~~~~~~~~~~~~~~~~~^^^^^^^^^^^^^^^
KeyError: 'Big Chances'
2025-09-18 21:00:12,882 - ERROR - Fail at 283: https://www.flashscore.com/match/football/augsburg-fTVNku3I/st-pauli-ILyJuN3g/?mid=CnrLfkNN
Traceback (most recent call last):
  File "c:\Users\GPbl3YH\Desktop\Study\PythonProjects\trash\football_stats_scraper\main.py", line 27, in <module>
    write_stats_to_database(m, conn)
  File "c:\Users\GPbl3YH\Desktop\Study\PythonProjects\trash\football_stats_scraper\common\utils.py", line 28, in write_stats_to_database
    (match.DATE, match.HOME, match.AWAY, match.STATS['full_time']['Ball Possession'][0], match.STATS['full_time']['Ball Possession'][1], match.STATS['full_time']['Total shots'][0], match.STATS['full_time']['Total shots'][1], match.STATS['full_time']['Shots on target'][0], match.STATS['full_time']['Shots on target'][1], match.STATS['full_time']['Big Chances'][0], match.STATS['full_time']['Big Chances'][1]))
                                                                                                                                                                                                                                                                                                                                 ~~~~~~~~~~~~~~~~~~~~~~~~^^^^^^^^^^^^^^^
KeyError: 'Big Chances'
2025-09-18 21:00:50,693 - ERROR - Fail at 284: https://www.flashscore.com/match/football/bayern-munich-nVp0wiqd/holstein-kiel-63WsD2ei/?mid=x4pn9lxH
Traceback (most recent call last):
  File "c:\Users\GPbl3YH\Desktop\Study\PythonProjects\trash\football_stats_scraper\main.py", line 27, in <module>
    write_stats_to_database(m, conn)
  File "c:\Users\GPbl3YH\Desktop\Study\PythonProjects\trash\football_stats_scraper\common\utils.py", line 28, in write_stats_to_database
    (match.DATE, match.HOME, match.AWAY, match.STATS['full_time']['Ball Possession'][0], match.STATS['full_time']['Ball Possession'][1], match.STATS['full_time']['Total shots'][0], match.STATS['full_time']['Total shots'][1], match.STATS['full_time']['Shots on target'][0], match.STATS['full_time']['Shots on target'][1], match.STATS['full_time']['Big Chances'][0], match.STATS['full_time']['Big Chances'][1]))
                                                                                                                                                                                                                                                                                                                                 ~~~~~~~~~~~~~~~~~~~~~~~~^^^^^^^^^^^^^^^
KeyError: 'Big Chances'
2025-09-18 21:01:25,395 - ERROR - Fail at 285: https://www.flashscore.com/match/football/b-monchengladbach-88HSzjDr/vfb-stuttgart-nJQmYp1B/?mid=UwsvBA74
Traceback (most recent call last):
  File "c:\Users\GPbl3YH\Desktop\Study\PythonProjects\trash\football_stats_scraper\main.py", line 27, in <module>
    write_stats_to_database(m, conn)
  File "c:\Users\GPbl3YH\Desktop\Study\PythonProjects\trash\football_stats_scraper\common\utils.py", line 28, in write_stats_to_database
    (match.DATE, match.HOME, match.AWAY, match.STATS['full_time']['Ball Possession'][0], match.STATS['full_time']['Ball Possession'][1], match.STATS['full_time']['Total shots'][0], match.STATS['full_time']['Total shots'][1], match.STATS['full_time']['Shots on target'][0], match.STATS['full_time']['Shots on target'][1], match.STATS['full_time']['Big Chances'][0], match.STATS['full_time']['Big Chances'][1]))
                                                                                                                                                                                                                                                                                                                                 ~~~~~~~~~~~~~~~~~~~~~~~~^^^^^^^^^^^^^^^
KeyError: 'Big Chances'
2025-09-18 21:02:00,678 - ERROR - Fail at 286: https://www.flashscore.com/match/football/bochum-8Y2m6ADe/freiburg-fiEQZ7C7/?mid=vZqDdBhB
Traceback (most recent call last):
  File "c:\Users\GPbl3YH\Desktop\Study\PythonProjects\trash\football_stats_scraper\main.py", line 27, in <module>
    write_stats_to_database(m, conn)
  File "c:\Users\GPbl3YH\Desktop\Study\PythonProjects\trash\football_stats_scraper\common\utils.py", line 28, in write_stats_to_database
    (match.DATE, match.HOME, match.AWAY, match.STATS['full_time']['Ball Possession'][0], match.STATS['full_time']['Ball Possession'][1], match.STATS['full_time']['Total shots'][0], match.STATS['full_time']['Total shots'][1], match.STATS['full_time']['Shots on target'][0], match.STATS['full_time']['Shots on target'][1], match.STATS['full_time']['Big Chances'][0], match.STATS['full_time']['Big Chances'][1]))
                                                                                                                                                                                                                                                                                                                                 ~~~~~~~~~~~~~~~~~~~~~~~~^^^^^^^^^^^^^^^
KeyError: 'Big Chances'
2025-09-18 21:02:36,773 - ERROR - Fail at 287: https://www.flashscore.com/match/football/bayer-leverkusen-4jcj2zMd/hoffenheim-hQAtP9Sl/?mid=r7j4bXNb
Traceback (most recent call last):
  File "c:\Users\GPbl3YH\Desktop\Study\PythonProjects\trash\football_stats_scraper\main.py", line 27, in <module>
    write_stats_to_database(m, conn)
  File "c:\Users\GPbl3YH\Desktop\Study\PythonProjects\trash\football_stats_scraper\common\utils.py", line 28, in write_stats_to_database
    (match.DATE, match.HOME, match.AWAY, match.STATS['full_time']['Ball Possession'][0], match.STATS['full_time']['Ball Possession'][1], match.STATS['full_time']['Total shots'][0], match.STATS['full_time']['Total shots'][1], match.STATS['full_time']['Shots on target'][0], match.STATS['full_time']['Shots on target'][1], match.STATS['full_time']['Big Chances'][0], match.STATS['full_time']['Big Chances'][1]))
                                                                                                                                                                                                                                                                                                                                 ~~~~~~~~~~~~~~~~~~~~~~~~^^^^^^^^^^^^^^^
KeyError: 'Big Chances'
2025-09-18 21:03:11,297 - ERROR - Fail at 288: https://www.flashscore.com/match/football/rb-leipzig-KbS1suSm/union-berlin-pzHW4oaE/?mid=WSMotj8U
Traceback (most recent call last):
  File "c:\Users\GPbl3YH\Desktop\Study\PythonProjects\trash\football_stats_scraper\main.py", line 27, in <module>
    write_stats_to_database(m, conn)
  File "c:\Users\GPbl3YH\Desktop\Study\PythonProjects\trash\football_stats_scraper\common\utils.py", line 28, in write_stats_to_database
    (match.DATE, match.HOME, match.AWAY, match.STATS['full_time']['Ball Possession'][0], match.STATS['full_time']['Ball Possession'][1], match.STATS['full_time']['Total shots'][0], match.STATS['full_time']['Total shots'][1], match.STATS['full_time']['Shots on target'][0], match.STATS['full_time']['Shots on target'][1], match.STATS['full_time']['Big Chances'][0], match.STATS['full_time']['Big Chances'][1]))
                                                                                                                                                                                                                                                                                                                                 ~~~~~~~~~~~~~~~~~~~~~~~~^^^^^^^^^^^^^^^
KeyError: 'Big Chances'
2025-09-18 21:03:46,254 - ERROR - Fail at 289: https://www.flashscore.com/match/football/eintracht-frankfurt-8vndvXTk/wolfsburg-nwkTahLL/?mid=tI0qkTpo
Traceback (most recent call last):
  File "c:\Users\GPbl3YH\Desktop\Study\PythonProjects\trash\football_stats_scraper\main.py", line 27, in <module>
    write_stats_to_database(m, conn)
  File "c:\Users\GPbl3YH\Desktop\Study\PythonProjects\trash\football_stats_scraper\common\utils.py", line 28, in write_stats_to_database
    (match.DATE, match.HOME, match.AWAY, match.STATS['full_time']['Ball Possession'][0], match.STATS['full_time']['Ball Possession'][1], match.STATS['full_time']['Total shots'][0], match.STATS['full_time']['Total shots'][1], match.STATS['full_time']['Shots on target'][0], match.STATS['full_time']['Shots on target'][1], match.STATS['full_time']['Big Chances'][0], match.STATS['full_time']['Big Chances'][1]))
                                                                                                                                                                                                                                                                                                                                 ~~~~~~~~~~~~~~~~~~~~~~~~^^^^^^^^^^^^^^^
KeyError: 'Big Chances'
2025-09-18 21:04:26,695 - ERROR - Fail at 290: https://www.flashscore.com/match/football/dortmund-nP1i5US1/heidenheim-KWixEVWi/?mid=zsmd0ggn
Traceback (most recent call last):
  File "c:\Users\GPbl3YH\Desktop\Study\PythonProjects\trash\football_stats_scraper\main.py", line 27, in <module>
    write_stats_to_database(m, conn)
  File "c:\Users\GPbl3YH\Desktop\Study\PythonProjects\trash\football_stats_scraper\common\utils.py", line 28, in write_stats_to_database
    (match.DATE, match.HOME, match.AWAY, match.STATS['full_time']['Ball Possession'][0], match.STATS['full_time']['Ball Possession'][1], match.STATS['full_time']['Total shots'][0], match.STATS['full_time']['Total shots'][1], match.STATS['full_time']['Shots on target'][0], match.STATS['full_time']['Shots on target'][1], match.STATS['full_time']['Big Chances'][0], match.STATS['full_time']['Big Chances'][1]))
                                                                                                                                                                                                                                                                                                                                 ~~~~~~~~~~~~~~~~~~~~~~~~^^^^^^^^^^^^^^^
KeyError: 'Big Chances'
2025-09-18 21:05:01,610 - ERROR - Fail at 291: https://www.flashscore.com/match/football/bayern-munich-nVp0wiqd/freiburg-fiEQZ7C7/?mid=2T6mXfPa
Traceback (most recent call last):
  File "c:\Users\GPbl3YH\Desktop\Study\PythonProjects\trash\football_stats_scraper\main.py", line 27, in <module>
    write_stats_to_database(m, conn)
  File "c:\Users\GPbl3YH\Desktop\Study\PythonProjects\trash\football_stats_scraper\common\utils.py", line 28, in write_stats_to_database
    (match.DATE, match.HOME, match.AWAY, match.STATS['full_time']['Ball Possession'][0], match.STATS['full_time']['Ball Possession'][1], match.STATS['full_time']['Total shots'][0], match.STATS['full_time']['Total shots'][1], match.STATS['full_time']['Shots on target'][0], match.STATS['full_time']['Shots on target'][1], match.STATS['full_time']['Big Chances'][0], match.STATS['full_time']['Big Chances'][1]))
                                                                                                                                                                                                                                                                                                                                 ~~~~~~~~~~~~~~~~~~~~~~~~^^^^^^^^^^^^^^^
KeyError: 'Big Chances'
2025-09-18 21:05:38,986 - ERROR - Fail at 292: https://www.flashscore.com/match/football/augsburg-fTVNku3I/heidenheim-KWixEVWi/?mid=W8b4TCOO
Traceback (most recent call last):
  File "c:\Users\GPbl3YH\Desktop\Study\PythonProjects\trash\football_stats_scraper\main.py", line 27, in <module>
    write_stats_to_database(m, conn)
  File "c:\Users\GPbl3YH\Desktop\Study\PythonProjects\trash\football_stats_scraper\common\utils.py", line 28, in write_stats_to_database
    (match.DATE, match.HOME, match.AWAY, match.STATS['full_time']['Ball Possession'][0], match.STATS['full_time']['Ball Possession'][1], match.STATS['full_time']['Total shots'][0], match.STATS['full_time']['Total shots'][1], match.STATS['full_time']['Shots on target'][0], match.STATS['full_time']['Shots on target'][1], match.STATS['full_time']['Big Chances'][0], match.STATS['full_time']['Big Chances'][1]))
                                                                                                                                                                                                                                                                                                                                 ~~~~~~~~~~~~~~~~~~~~~~~~^^^^^^^^^^^^^^^
KeyError: 'Big Chances'
2025-09-18 21:06:13,778 - ERROR - Fail at 293: https://www.flashscore.com/match/football/bayer-leverkusen-4jcj2zMd/rb-leipzig-KbS1suSm/?mid=AVR8vwXP
Traceback (most recent call last):
  File "c:\Users\GPbl3YH\Desktop\Study\PythonProjects\trash\football_stats_scraper\main.py", line 27, in <module>
    write_stats_to_database(m, conn)
  File "c:\Users\GPbl3YH\Desktop\Study\PythonProjects\trash\football_stats_scraper\common\utils.py", line 28, in write_stats_to_database
    (match.DATE, match.HOME, match.AWAY, match.STATS['full_time']['Ball Possession'][0], match.STATS['full_time']['Ball Possession'][1], match.STATS['full_time']['Total shots'][0], match.STATS['full_time']['Total shots'][1], match.STATS['full_time']['Shots on target'][0], match.STATS['full_time']['Shots on target'][1], match.STATS['full_time']['Big Chances'][0], match.STATS['full_time']['Big Chances'][1]))
                                                                                                                                                                                                                                                                                                                                 ~~~~~~~~~~~~~~~~~~~~~~~~^^^^^^^^^^^^^^^
KeyError: 'Big Chances'
2025-09-18 21:06:50,620 - ERROR - Fail at 294: https://www.flashscore.com/match/football/b-monchengladbach-88HSzjDr/bochum-8Y2m6ADe/?mid=U3QUqY85
Traceback (most recent call last):
  File "c:\Users\GPbl3YH\Desktop\Study\PythonProjects\trash\football_stats_scraper\main.py", line 27, in <module>
    write_stats_to_database(m, conn)
  File "c:\Users\GPbl3YH\Desktop\Study\PythonProjects\trash\football_stats_scraper\common\utils.py", line 28, in write_stats_to_database
    (match.DATE, match.HOME, match.AWAY, match.STATS['full_time']['Ball Possession'][0], match.STATS['full_time']['Ball Possession'][1], match.STATS['full_time']['Total shots'][0], match.STATS['full_time']['Total shots'][1], match.STATS['full_time']['Shots on target'][0], match.STATS['full_time']['Shots on target'][1], match.STATS['full_time']['Big Chances'][0], match.STATS['full_time']['Big Chances'][1]))
                                                                                                                                                                                                                                                                                                                                 ~~~~~~~~~~~~~~~~~~~~~~~~^^^^^^^^^^^^^^^
KeyError: 'Big Chances'
2025-09-18 21:07:24,635 - ERROR - Fail at 295: https://www.flashscore.com/match/football/eintracht-frankfurt-8vndvXTk/hoffenheim-hQAtP9Sl/?mid=AgAeVYgC
Traceback (most recent call last):
  File "c:\Users\GPbl3YH\Desktop\Study\PythonProjects\trash\football_stats_scraper\main.py", line 27, in <module>
    write_stats_to_database(m, conn)
  File "c:\Users\GPbl3YH\Desktop\Study\PythonProjects\trash\football_stats_scraper\common\utils.py", line 28, in write_stats_to_database
    (match.DATE, match.HOME, match.AWAY, match.STATS['full_time']['Ball Possession'][0], match.STATS['full_time']['Ball Possession'][1], match.STATS['full_time']['Total shots'][0], match.STATS['full_time']['Total shots'][1], match.STATS['full_time']['Shots on target'][0], match.STATS['full_time']['Shots on target'][1], match.STATS['full_time']['Big Chances'][0], match.STATS['full_time']['Big Chances'][1]))
                                                                                                                                                                                                                                                                                                                                 ~~~~~~~~~~~~~~~~~~~~~~~~^^^^^^^^^^^^^^^
KeyError: 'Big Chances'
2025-09-18 21:08:01,914 - ERROR - Fail at 296: https://www.flashscore.com/match/football/holstein-kiel-63WsD2ei/wolfsburg-nwkTahLL/?mid=QVJwrCwI
Traceback (most recent call last):
  File "c:\Users\GPbl3YH\Desktop\Study\PythonProjects\trash\football_stats_scraper\main.py", line 27, in <module>
    write_stats_to_database(m, conn)
  File "c:\Users\GPbl3YH\Desktop\Study\PythonProjects\trash\football_stats_scraper\common\utils.py", line 28, in write_stats_to_database
    (match.DATE, match.HOME, match.AWAY, match.STATS['full_time']['Ball Possession'][0], match.STATS['full_time']['Ball Possession'][1], match.STATS['full_time']['Total shots'][0], match.STATS['full_time']['Total shots'][1], match.STATS['full_time']['Shots on target'][0], match.STATS['full_time']['Shots on target'][1], match.STATS['full_time']['Big Chances'][0], match.STATS['full_time']['Big Chances'][1]))
                                                                                                                                                                                                                                                                                                                                 ~~~~~~~~~~~~~~~~~~~~~~~~^^^^^^^^^^^^^^^
KeyError: 'Big Chances'
2025-09-18 21:08:37,708 - ERROR - Fail at 297: https://www.flashscore.com/match/football/mainz-EuakNmc1/vfb-stuttgart-nJQmYp1B/?mid=61DvZGfm
Traceback (most recent call last):
  File "c:\Users\GPbl3YH\Desktop\Study\PythonProjects\trash\football_stats_scraper\main.py", line 27, in <module>
    write_stats_to_database(m, conn)
  File "c:\Users\GPbl3YH\Desktop\Study\PythonProjects\trash\football_stats_scraper\common\utils.py", line 28, in write_stats_to_database
    (match.DATE, match.HOME, match.AWAY, match.STATS['full_time']['Ball Possession'][0], match.STATS['full_time']['Ball Possession'][1], match.STATS['full_time']['Total shots'][0], match.STATS['full_time']['Total shots'][1], match.STATS['full_time']['Shots on target'][0], match.STATS['full_time']['Shots on target'][1], match.STATS['full_time']['Big Chances'][0], match.STATS['full_time']['Big Chances'][1]))
                                                                                                                                                                                                                                                                                                                                 ~~~~~~~~~~~~~~~~~~~~~~~~^^^^^^^^^^^^^^^
KeyError: 'Big Chances'
2025-09-18 21:09:12,607 - ERROR - Fail at 298: https://www.flashscore.com/match/football/dortmund-nP1i5US1/werder-bremen-Ig1f1fy3/?mid=0OYDmG9t
Traceback (most recent call last):
  File "c:\Users\GPbl3YH\Desktop\Study\PythonProjects\trash\football_stats_scraper\main.py", line 27, in <module>
    write_stats_to_database(m, conn)
  File "c:\Users\GPbl3YH\Desktop\Study\PythonProjects\trash\football_stats_scraper\common\utils.py", line 28, in write_stats_to_database
    (match.DATE, match.HOME, match.AWAY, match.STATS['full_time']['Ball Possession'][0], match.STATS['full_time']['Ball Possession'][1], match.STATS['full_time']['Total shots'][0], match.STATS['full_time']['Total shots'][1], match.STATS['full_time']['Shots on target'][0], match.STATS['full_time']['Shots on target'][1], match.STATS['full_time']['Big Chances'][0], match.STATS['full_time']['Big Chances'][1]))
                                                                                                                                                                                                                                                                                                                                 ~~~~~~~~~~~~~~~~~~~~~~~~^^^^^^^^^^^^^^^
KeyError: 'Big Chances'
2025-09-18 21:09:48,164 - ERROR - Fail at 299: https://www.flashscore.com/match/football/st-pauli-ILyJuN3g/union-berlin-pzHW4oaE/?mid=djSMofvg
Traceback (most recent call last):
  File "c:\Users\GPbl3YH\Desktop\Study\PythonProjects\trash\football_stats_scraper\main.py", line 27, in <module>
    write_stats_to_database(m, conn)
  File "c:\Users\GPbl3YH\Desktop\Study\PythonProjects\trash\football_stats_scraper\common\utils.py", line 28, in write_stats_to_database
    (match.DATE, match.HOME, match.AWAY, match.STATS['full_time']['Ball Possession'][0], match.STATS['full_time']['Ball Possession'][1], match.STATS['full_time']['Total shots'][0], match.STATS['full_time']['Total shots'][1], match.STATS['full_time']['Shots on target'][0], match.STATS['full_time']['Shots on target'][1], match.STATS['full_time']['Big Chances'][0], match.STATS['full_time']['Big Chances'][1]))
                                                                                                                                                                                                                                                                                                                                 ~~~~~~~~~~~~~~~~~~~~~~~~^^^^^^^^^^^^^^^
KeyError: 'Big Chances'
2025-09-18 21:10:24,036 - ERROR - Fail at 300: https://www.flashscore.com/match/football/heidenheim-KWixEVWi/st-pauli-ILyJuN3g/?mid=AuVMGZvJ
Traceback (most recent call last):
  File "c:\Users\GPbl3YH\Desktop\Study\PythonProjects\trash\football_stats_scraper\main.py", line 27, in <module>
    write_stats_to_database(m, conn)
  File "c:\Users\GPbl3YH\Desktop\Study\PythonProjects\trash\football_stats_scraper\common\utils.py", line 28, in write_stats_to_database
    (match.DATE, match.HOME, match.AWAY, match.STATS['full_time']['Ball Possession'][0], match.STATS['full_time']['Ball Possession'][1], match.STATS['full_time']['Total shots'][0], match.STATS['full_time']['Total shots'][1], match.STATS['full_time']['Shots on target'][0], match.STATS['full_time']['Shots on target'][1], match.STATS['full_time']['Big Chances'][0], match.STATS['full_time']['Big Chances'][1]))
                                                                                                                                                                                                                                                                                                                                 ~~~~~~~~~~~~~~~~~~~~~~~~^^^^^^^^^^^^^^^
KeyError: 'Big Chances'
2025-09-18 21:11:00,066 - ERROR - Fail at 301: https://www.flashscore.com/match/football/bayern-munich-nVp0wiqd/wolfsburg-nwkTahLL/?mid=t0w6KHuf
Traceback (most recent call last):
  File "c:\Users\GPbl3YH\Desktop\Study\PythonProjects\trash\football_stats_scraper\main.py", line 27, in <module>
    write_stats_to_database(m, conn)
  File "c:\Users\GPbl3YH\Desktop\Study\PythonProjects\trash\football_stats_scraper\common\utils.py", line 28, in write_stats_to_database
    (match.DATE, match.HOME, match.AWAY, match.STATS['full_time']['Ball Possession'][0], match.STATS['full_time']['Ball Possession'][1], match.STATS['full_time']['Total shots'][0], match.STATS['full_time']['Total shots'][1], match.STATS['full_time']['Shots on target'][0], match.STATS['full_time']['Shots on target'][1], match.STATS['full_time']['Big Chances'][0], match.STATS['full_time']['Big Chances'][1]))
                                                                                                                                                                                                                                                                                                                                 ~~~~~~~~~~~~~~~~~~~~~~~~^^^^^^^^^^^^^^^
KeyError: 'Big Chances'
2025-09-18 21:11:34,435 - ERROR - Fail at 302: https://www.flashscore.com/match/football/dortmund-nP1i5US1/eintracht-frankfurt-8vndvXTk/?mid=SxFxJ44k
Traceback (most recent call last):
  File "c:\Users\GPbl3YH\Desktop\Study\PythonProjects\trash\football_stats_scraper\main.py", line 27, in <module>
    write_stats_to_database(m, conn)
  File "c:\Users\GPbl3YH\Desktop\Study\PythonProjects\trash\football_stats_scraper\common\utils.py", line 28, in write_stats_to_database
    (match.DATE, match.HOME, match.AWAY, match.STATS['full_time']['Ball Possession'][0], match.STATS['full_time']['Ball Possession'][1], match.STATS['full_time']['Total shots'][0], match.STATS['full_time']['Total shots'][1], match.STATS['full_time']['Shots on target'][0], match.STATS['full_time']['Shots on target'][1], match.STATS['full_time']['Big Chances'][0], match.STATS['full_time']['Big Chances'][1]))
                                                                                                                                                                                                                                                                                                                                 ~~~~~~~~~~~~~~~~~~~~~~~~^^^^^^^^^^^^^^^
KeyError: 'Big Chances'
2025-09-18 21:12:09,057 - ERROR - Fail at 303: https://www.flashscore.com/match/football/augsburg-fTVNku3I/werder-bremen-Ig1f1fy3/?mid=YZZcMwBs
Traceback (most recent call last):
  File "c:\Users\GPbl3YH\Desktop\Study\PythonProjects\trash\football_stats_scraper\main.py", line 27, in <module>
    write_stats_to_database(m, conn)
  File "c:\Users\GPbl3YH\Desktop\Study\PythonProjects\trash\football_stats_scraper\common\utils.py", line 28, in write_stats_to_database
    (match.DATE, match.HOME, match.AWAY, match.STATS['full_time']['Ball Possession'][0], match.STATS['full_time']['Ball Possession'][1], match.STATS['full_time']['Total shots'][0], match.STATS['full_time']['Total shots'][1], match.STATS['full_time']['Shots on target'][0], match.STATS['full_time']['Shots on target'][1], match.STATS['full_time']['Big Chances'][0], match.STATS['full_time']['Big Chances'][1]))
                                                                                                                                                                                                                                                                                                                                 ~~~~~~~~~~~~~~~~~~~~~~~~^^^^^^^^^^^^^^^
KeyError: 'Big Chances'
2025-09-18 21:12:44,369 - ERROR - Fail at 304: https://www.flashscore.com/match/football/freiburg-fiEQZ7C7/vfb-stuttgart-nJQmYp1B/?mid=GbeXvnR8
Traceback (most recent call last):
  File "c:\Users\GPbl3YH\Desktop\Study\PythonProjects\trash\football_stats_scraper\main.py", line 27, in <module>
    write_stats_to_database(m, conn)
  File "c:\Users\GPbl3YH\Desktop\Study\PythonProjects\trash\football_stats_scraper\common\utils.py", line 28, in write_stats_to_database
    (match.DATE, match.HOME, match.AWAY, match.STATS['full_time']['Ball Possession'][0], match.STATS['full_time']['Ball Possession'][1], match.STATS['full_time']['Total shots'][0], match.STATS['full_time']['Total shots'][1], match.STATS['full_time']['Shots on target'][0], match.STATS['full_time']['Shots on target'][1], match.STATS['full_time']['Big Chances'][0], match.STATS['full_time']['Big Chances'][1]))
                                                                                                                                                                                                                                                                                                                                 ~~~~~~~~~~~~~~~~~~~~~~~~^^^^^^^^^^^^^^^
KeyError: 'Big Chances'
2025-09-18 21:13:18,986 - ERROR - Fail at 305: https://www.flashscore.com/match/football/hoffenheim-hQAtP9Sl/holstein-kiel-63WsD2ei/?mid=O48oHrZ1
Traceback (most recent call last):
  File "c:\Users\GPbl3YH\Desktop\Study\PythonProjects\trash\football_stats_scraper\main.py", line 27, in <module>
    write_stats_to_database(m, conn)
  File "c:\Users\GPbl3YH\Desktop\Study\PythonProjects\trash\football_stats_scraper\common\utils.py", line 28, in write_stats_to_database
    (match.DATE, match.HOME, match.AWAY, match.STATS['full_time']['Ball Possession'][0], match.STATS['full_time']['Ball Possession'][1], match.STATS['full_time']['Total shots'][0], match.STATS['full_time']['Total shots'][1], match.STATS['full_time']['Shots on target'][0], match.STATS['full_time']['Shots on target'][1], match.STATS['full_time']['Big Chances'][0], match.STATS['full_time']['Big Chances'][1]))
                                                                                                                                                                                                                                                                                                                                 ~~~~~~~~~~~~~~~~~~~~~~~~^^^^^^^^^^^^^^^
KeyError: 'Big Chances'
2025-09-18 21:13:53,167 - ERROR - Fail at 306: https://www.flashscore.com/match/football/mainz-EuakNmc1/union-berlin-pzHW4oaE/?mid=2FREIeA6
Traceback (most recent call last):
  File "c:\Users\GPbl3YH\Desktop\Study\PythonProjects\trash\football_stats_scraper\main.py", line 27, in <module>
    write_stats_to_database(m, conn)
  File "c:\Users\GPbl3YH\Desktop\Study\PythonProjects\trash\football_stats_scraper\common\utils.py", line 28, in write_stats_to_database
    (match.DATE, match.HOME, match.AWAY, match.STATS['full_time']['Ball Possession'][0], match.STATS['full_time']['Ball Possession'][1], match.STATS['full_time']['Total shots'][0], match.STATS['full_time']['Total shots'][1], match.STATS['full_time']['Shots on target'][0], match.STATS['full_time']['Shots on target'][1], match.STATS['full_time']['Big Chances'][0], match.STATS['full_time']['Big Chances'][1]))
                                                                                                                                                                                                                                                                                                                                 ~~~~~~~~~~~~~~~~~~~~~~~~^^^^^^^^^^^^^^^
KeyError: 'Big Chances'
2025-09-18 21:14:28,830 - ERROR - Fail at 307: https://www.flashscore.com/match/football/bochum-8Y2m6ADe/rb-leipzig-KbS1suSm/?mid=dfO6OQtS
Traceback (most recent call last):
  File "c:\Users\GPbl3YH\Desktop\Study\PythonProjects\trash\football_stats_scraper\main.py", line 27, in <module>
    write_stats_to_database(m, conn)
  File "c:\Users\GPbl3YH\Desktop\Study\PythonProjects\trash\football_stats_scraper\common\utils.py", line 28, in write_stats_to_database
    (match.DATE, match.HOME, match.AWAY, match.STATS['full_time']['Ball Possession'][0], match.STATS['full_time']['Ball Possession'][1], match.STATS['full_time']['Total shots'][0], match.STATS['full_time']['Total shots'][1], match.STATS['full_time']['Shots on target'][0], match.STATS['full_time']['Shots on target'][1], match.STATS['full_time']['Big Chances'][0], match.STATS['full_time']['Big Chances'][1]))
                                                                                                                                                                                                                                                                                                                                 ~~~~~~~~~~~~~~~~~~~~~~~~^^^^^^^^^^^^^^^
KeyError: 'Big Chances'
2025-09-18 21:15:03,027 - ERROR - Fail at 308: https://www.flashscore.com/match/football/b-monchengladbach-88HSzjDr/bayer-leverkusen-4jcj2zMd/?mid=zuzbQnCF
Traceback (most recent call last):
  File "c:\Users\GPbl3YH\Desktop\Study\PythonProjects\trash\football_stats_scraper\main.py", line 27, in <module>
    write_stats_to_database(m, conn)
  File "c:\Users\GPbl3YH\Desktop\Study\PythonProjects\trash\football_stats_scraper\common\utils.py", line 28, in write_stats_to_database
    (match.DATE, match.HOME, match.AWAY, match.STATS['full_time']['Ball Possession'][0], match.STATS['full_time']['Ball Possession'][1], match.STATS['full_time']['Total shots'][0], match.STATS['full_time']['Total shots'][1], match.STATS['full_time']['Shots on target'][0], match.STATS['full_time']['Shots on target'][1], match.STATS['full_time']['Big Chances'][0], match.STATS['full_time']['Big Chances'][1]))
                                                                                                                                                                                                                                                                                                                                 ~~~~~~~~~~~~~~~~~~~~~~~~^^^^^^^^^^^^^^^
KeyError: 'Big Chances'
